Workbook

Sheet Cover
B3: Hedge Fund-Grade Equity Analysis
B5: Financial Model Template v2.1
B8: Ticker: | C8: TSLA
B9: Company: | C9: Tesla, Inc.
B10: Exchange: | C10: NASDAQ
B11: Analysis Date: | C11: 2026-03-10
B12: Analyst: | C12: AI Multi-Agent System v2.1
B13: Methodology: | C13: 16 Agents, 93 Dimensions, Consensus-Calibrated
B16: Tab Guide:
B17: 1. Cover | C17: This page — ticker info & metadata
B18: 2. Assumptions | C18: All key assumptions (blue = editable inputs)
B19: 3. Income Statement | C19: 5yr historical + 5yr projected P&L
B20: 4. Balance Sheet | C20: Assets, liabilities, equity
B21: 5. Cash Flow | C21: Operating, investing, financing cash flows
B22: 6. Revenue Build | C22: Segment-level revenue decomposition
B23: 7. DCF Valuation | C23: Discounted cash flow with WACC
B24: 8. SOTP Valuation | C24: Sum-of-the-parts with real options
B25: 9. Scenario Analysis | C25: Probability-weighted scenarios (5 cases)
B26: 10. Comps | C26: Trading & transaction comparables
B27: 11. Agent Scores | C27: 16-agent conviction heatmap
B28: 12. Catalyst Calendar | C28: Event-driven catalysts with probabilities
B29: 13. Position Sizing | C29: Kelly criterion & entry strategy
B32: Color Legend:
B33: Blue text | C33: hardcoded inputs (editable)
B34: Black text | C34: formulas & calculations
B35: Green text | C35: links from other sheets
C36: key assumptions to review

Sheet Assumptions
A1: KEY ASSUMPTIONS
A2: All blue cells are editable inputs. Change these to run scenarios.
A4: Assumption | B4: 2022A | C4: 2023A | D4: 2024A | E4: 2025E | F4: 2026E | G4: 2027E | H4: 2028E | I4: 2029E | J4: 2030E
A5: REVENUE ASSUMPTIONS
A6: Auto Revenue Growth % | C6: 0.15 | D6: 0.01 | E6: 0.12 | F6: 0.18 | G6: 0.2 | H6: 0.18 | I6: 0.15 | J6: 0.12
A7: Energy Revenue Growth % | C7: 0.4 | D7: 0.54 | E7: 0.81 | F7: 0.6 | G7: 0.5 | H7: 0.45 | I7: 0.4 | J7: 0.35
A8: Services Revenue Growth % | C8: 0.3 | D8: 0.25 | E8: 0.2 | F8: 0.25 | G8: 0.22 | H8: 0.2 | I8: 0.18 | J8: 0.15
A9: Auto Revenue ($M) | B9: 71462 | C9: 82419 | D9: 83205 | E9: 93190 | F9: 109964 | G9: 131957 | H9: 155710 | I9: 179067 | J9: 200555
A10: Energy Revenue ($M) | B10: 3909 | C10: 6035 | D10: 10382 | E10: 18791 | F10: 30066 | G10: 45099 | H10: 65393 | I10: 91550 | J10: 123593
A11: Services Revenue ($M) | B11: 6091 | C11: 8319 | D11: 10467 | E11: 12560 | F11: 15700 | G11: 19154 | H11: 22985 | I11: 27122 | J11: 31190
A13: MARGIN ASSUMPTIONS
A14: Gross Margin % | B14: 0.256 | C14: 0.183 | D14: 0.178 | E14: 0.182 | F14: 0.195 | G14: 0.21 | H14: 0.225 | I14: 0.235 | J14: 0.245
A15: R&D % of Revenue | B15: 0.05 | C15: 0.048 | D15: 0.046 | E15: 0.044 | F15: 0.042 | G15: 0.04 | H15: 0.038 | I15: 0.036 | J15: 0.035
A16: SGA % of Revenue | B16: 0.04 | C16: 0.038 | D16: 0.036 | E16: 0.034 | F16: 0.032 | G16: 0.03 | H16: 0.028 | I16: 0.026 | J16: 0.025
A17: D&A % of Revenue | B17: 0.045 | C17: 0.048 | D17: 0.05 | E17: 0.048 | F17: 0.046 | G17: 0.044 | H17: 0.042 | I17: 0.04 | J17: 0.038
A18: Operating Margin % | B18: 0.168 | C18: 0.092 | D18: 0.087 | E18: 0.095 | F18: 0.115 | G18: 0.135 | H18: 0.155 | I18: 0.17 | J18: 0.185
A19: Tax Rate % | B19: 0.08 | C19: 0.1 | D19: 0.12 | E19: 0.14 | F19: 0.15 | G19: 0.16 | H19: 0.17 | I19: 0.18 | J19: 0.18
A22: CAPITAL & VALUATION ASSUMPTIONS
A23: CapEx % of Revenue | B23: 0.065 | C23: 0.075 | D23: 0.085 | E23: 0.08 | F23: 0.075 | G23: 0.07 | H23: 0.065 | I23: 0.06 | J23: 0.055
A24: Working Capital % of Rev Change | B24: 0.02 | C24: 0.03 | D24: 0.03 | E24: 0.03 | F24: 0.03 | G24: 0.03 | H24: 0.03 | I24: 0.03 | J24: 0.03
A25: Shares Outstanding (M) | B25: 3475 | C25: 3485 | D25: 3495 | E25: 3510 | F25: 3530 | G25: 3555 | H25: 3580 | I25: 3610 | J25: 3640
A26: Risk-Free Rate % | B26: 0.043 | E26: 0.042 | F26: 0.042 | G26: 0.042 | H26: 0.042 | I26: 0.042 | J26: 0.042
A27: Equity Risk Premium % | B27: 0.055 | E27: 0.055 | F27: 0.055 | G27: 0.055 | H27: 0.055 | I27: 0.055 | J27: 0.055
A28: Beta | B28: 1.85 | E28: 1.8 | F28: 1.8 | G28: 1.8 | H28: 1.8 | I28: 1.8 | J28: 1.8
A29: Terminal Growth Rate % | B29: 0.03 | E29: 0.03 | F29: 0.03 | G29: 0.03 | H29: 0.03 | I29: 0.03 | J29: 0.03
A30: Current Stock Price | B30: 401 | E30: 401

Sheet Income Statement
A1: CONSOLIDATED INCOME STATEMENT
A2: ($ in millions, except per share data)
A4: Income Statement ($M) | B4: 2022A | C4: 2023A | D4: 2024A | E4: 2025E | F4: 2026E | G4: 2027E | H4: 2028E | I4: 2029E | J4: 2030E
A5: REVENUE
A6: Automotive Revenue | B6: =Assumptions!B9 -> 71462 | C6: =Assumptions!C9 -> 82419 | D6: =Assumptions!D9 -> 83205 | E6: =Assumptions!E9 -> 93190 | F6: =Assumptions!F9 -> 109964 | G6: =Assumptions!G9 -> 131957 | H6: =Assumptions!H9 -> 155710 | I6: =Assumptions!I9 -> 179067 | J6: =Assumptions!J9 -> 200555
A7: Energy Gen & Storage | B7: =Assumptions!B10 -> 3909 | C7: =Assumptions!C10 -> 6035 | D7: =Assumptions!D10 -> 10382 | E7: =Assumptions!E10 -> 18791 | F7: =Assumptions!F10 -> 30066 | G7: =Assumptions!G10 -> 45099 | H7: =Assumptions!H10 -> 65393 | I7: =Assumptions!I10 -> 91550 | J7: =Assumptions!J10 -> 123593
A8: Services & Other | B8: =Assumptions!B11 -> 6091 | C8: =Assumptions!C11 -> 8319 | D8: =Assumptions!D11 -> 10467 | E8: =Assumptions!E11 -> 12560 | F8: =Assumptions!F11 -> 15700 | G8: =Assumptions!G11 -> 19154 | H8: =Assumptions!H11 -> 22985 | I8: =Assumptions!I11 -> 27122 | J8: =Assumptions!J11 -> 31190
A9: Total Revenue | B9: =SUM(B6:B8) -> 81462 | C9: =SUM(C6:C8) -> 96773 | D9: =SUM(D6:D8) -> 104054 | E9: =SUM(E6:E8) -> 124541 | F9: =SUM(F6:F8) -> 155730 | G9: =SUM(G6:G8) -> 196210 | H9: =SUM(H6:H8) -> 244088 | I9: =SUM(I6:I8) -> 297739 | J9: =SUM(J6:J8) -> 355338
A10: YoY Growth % | C10: =IFERROR((C9-B9)/B9,0) -> 0.18795267 | D10: =IFERROR((D9-C9)/C9,0) -> 0.075237928 | E10: =IFERROR((E9-D9)/D9,0) -> 0.19688815 | F10: =IFERROR((F9-E9)/E9,0) -> 0.25043158 | G10: =IFERROR((G9-F9)/F9,0) -> 0.25993707 | H10: =IFERROR((H9-G9)/G9,0) -> 0.24401407 | I10: =IFERROR((I9-H9)/H9,0) -> 0.21980187 | J10: =IFERROR((J9-I9)/I9,0) -> 0.19345467
A12: COST OF GOODS SOLD & GROSS PROFIT
A13: Cost of Revenue | B13: =-B9*(1-Assumptions!B14) -> -60607.728 | C13: =-C9*(1-Assumptions!C14) -> -79063.541 | D13: =-D9*(1-Assumptions!D14) -> -85532.388 | E13: =-E9*(1-Assumptions!E14) -> -101874.54 | F13: =-F9*(1-Assumptions!F14) -> -125362.65 | G13: =-G9*(1-Assumptions!G14) -> -155005.9 | H13: =-H9*(1-Assumptions!H14) -> -189168.2 | I13: =-I9*(1-Assumptions!I14) -> -227770.33 | J13: =-J9*(1-Assumptions!J14) -> -268280.19
A14: Gross Profit | B14: =B9+B13 -> 20854.272 | C14: =C9+C13 -> 17709.459 | D14: =D9+D13 -> 18521.612 | E14: =E9+E13 -> 22666.462 | F14: =F9+F13 -> 30367.35 | G14: =G9+G13 -> 41204.1 | H14: =H9+H13 -> 54919.8 | I14: =I9+I13 -> 69968.665 | J14: =J9+J13 -> 87057.81
A15: Gross Margin % | B15: =IFERROR(B14/B9,0) -> 0.256 | C15: =IFERROR(C14/C9,0) -> 0.183 | D15: =IFERROR(D14/D9,0) -> 0.178 | E15: =IFERROR(E14/E9,0) -> 0.182 | F15: =IFERROR(F14/F9,0) -> 0.195 | G15: =IFERROR(G14/G9,0) -> 0.21 | H15: =IFERROR(H14/H9,0) -> 0.225 | I15: =IFERROR(I14/I9,0) -> 0.235 | J15: =IFERROR(J14/J9,0) -> 0.245
A17: OPERATING EXPENSES
A18: Research & Development | B18: =-B9*Assumptions!B15 -> -4073.1 | C18: =-C9*Assumptions!C15 -> -4645.104 | D18: =-D9*Assumptions!D15 -> -4786.484 | E18: =-E9*Assumptions!E15 -> -5479.804 | F18: =-F9*Assumptions!F15 -> -6540.66 | G18: =-G9*Assumptions!G15 -> -7848.4 | H18: =-H9*Assumptions!H15 -> -9275.344 | I18: =-I9*Assumptions!I15 -> -10718.604 | J18: =-J9*Assumptions!J15 -> -12436.83
A19: Selling, General & Admin | B19: =-B9*Assumptions!B16 -> -3258.48 | C19: =-C9*Assumptions!C16 -> -3677.374 | D19: =-D9*Assumptions!D16 -> -3745.944 | E19: =-E9*Assumptions!E16 -> -4234.394 | F19: =-F9*Assumptions!F16 -> -4983.36 | G19: =-G9*Assumptions!G16 -> -5886.3 | H19: =-H9*Assumptions!H16 -> -6834.464 | I19: =-I9*Assumptions!I16 -> -7741.214 | J19: =-J9*Assumptions!J16 -> -8883.45
A20: Depreciation & Amortization | B20: =-B9*Assumptions!B17 -> -3665.79 | C20: =-C9*Assumptions!C17 -> -4645.104 | D20: =-D9*Assumptions!D17 -> -5202.7 | E20: =-E9*Assumptions!E17 -> -5977.968 | F20: =-F9*Assumptions!F17 -> -7163.58 | G20: =-G9*Assumptions!G17 -> -8633.24 | H20: =-H9*Assumptions!H17 -> -10251.696 | I20: =-I9*Assumptions!I17 -> -11909.56 | J20: =-J9*Assumptions!J17 -> -13502.844
A21: Total Operating Expenses | B21: =SUM(B18:B20) -> -10997.37 | C21: =SUM(C18:C20) -> -12967.582 | D21: =SUM(D18:D20) -> -13735.128 | E21: =SUM(E18:E20) -> -15692.166 | F21: =SUM(F18:F20) -> -18687.6 | G21: =SUM(G18:G20) -> -22367.94 | H21: =SUM(H18:H20) -> -26361.504 | I21: =SUM(I18:I20) -> -30369.378 | J21: =SUM(J18:J20) -> -34823.124
A23: EBIT (Operating Income) | B23: =B14+B21 -> 9856.902 | C23: =C14+C21 -> 4741.877 | D23: =D14+D21 -> 4786.484 | E23: =E14+E21 -> 6974.296 | F23: =F14+F21 -> 11679.75 | G23: =G14+G21 -> 18836.16 | H23: =H14+H21 -> 28558.296 | I23: =I14+I21 -> 39599.287 | J23: =J14+J21 -> 52234.686
A24: Operating Margin % | B24: =IFERROR(B23/B9,0) -> 0.121 | C24: =IFERROR(C23/C9,0) -> 0.049 | D24: =IFERROR(D23/D9,0) -> 0.046 | E24: =IFERROR(E23/E9,0) -> 0.056 | F24: =IFERROR(F23/F9,0) -> 0.075 | G24: =IFERROR(G23/G9,0) -> 0.096 | H24: =IFERROR(H23/H9,0) -> 0.117 | I24: =IFERROR(I23/I9,0) -> 0.133 | J24: =IFERROR(J23/J9,0) -> 0.147
A26: Interest Expense (Net) | B26: -300 | C26: -300 | D26: -300 | E26: -300 | F26: -300 | G26: -300 | H26: -300 | I26: -300 | J26: -300
A27: Earnings Before Tax | B27: =B23+B26 -> 9556.902 | C27: =C23+C26 -> 4441.877 | D27: =D23+D26 -> 4486.484 | E27: =E23+E26 -> 6674.296 | F27: =F23+F26 -> 11379.75 | G27: =G23+G26 -> 18536.16 | H27: =H23+H26 -> 28258.296 | I27: =I23+I26 -> 39299.287 | J27: =J23+J26 -> 51934.686
A28: Income Tax | B28: =-ABS(B27)*Assumptions!B19 -> -764.55216 | C28: =-ABS(C27)*Assumptions!C19 -> -444.1877 | D28: =-ABS(D27)*Assumptions!D19 -> -538.37808 | E28: =-ABS(E27)*Assumptions!E19 -> -934.40144 | F28: =-ABS(F27)*Assumptions!F19 -> -1706.9625 | G28: =-ABS(G27)*Assumptions!G19 -> -2965.7856 | H28: =-ABS(H27)*Assumptions!H19 -> -4803.9103 | I28: =-ABS(I27)*Assumptions!I19 -> -7073.8717 | J28: =-ABS(J27)*Assumptions!J19 -> -9348.2435
A30: NET INCOME | B30: =B27+B28 -> 8792.3498 | C30: =C27+C28 -> 3997.6893 | D30: =D27+D28 -> 3948.1059 | E30: =E27+E28 -> 5739.8946 | F30: =F27+F28 -> 9672.7875 | G30: =G27+G28 -> 15570.374 | H30: =H27+H28 -> 23454.386 | I30: =I27+I28 -> 32225.415 | J30: =J27+J28 -> 42586.443
A31: Diluted EPS | B31: =IFERROR(B30/Assumptions!B25,0) -> 2.5301726 | C31: =IFERROR(C30/Assumptions!C24,0) -> 133256.31 | D31: =IFERROR(D30/Assumptions!D24,0) -> 131603.53 | E31: =IFERROR(E30/Assumptions!E24,0) -> 191329.82 | F31: =IFERROR(F30/Assumptions!F24,0) -> 322426.25 | G31: =IFERROR(G30/Assumptions!G24,0) -> 519012.48 | H31: =IFERROR(H30/Assumptions!H24,0) -> 781812.86 | I31: =IFERROR(I30/Assumptions!I24,0) -> 1074180.5 | J31: =IFERROR(J30/Assumptions!J24,0) -> 1419548.1
A33: EBITDA | B33: =B23-B20 -> 13522.692 | C33: =C23-C20 -> 9386.981 | D33: =D23-D20 -> 9989.184 | E33: =E23-E20 -> 12952.264 | F33: =F23-F20 -> 18843.33 | G33: =G23-G20 -> 27469.4 | H33: =H23-H20 -> 38809.992 | I33: =I23-I20 -> 51508.847 | J33: =J23-J20 -> 65737.53
A34: EBITDA Margin % | B34: =IFERROR(B33/B9,0) -> 0.166 | C34: =IFERROR(C33/C9,0) -> 0.097 | D34: =IFERROR(D33/D9,0) -> 0.096 | E34: =IFERROR(E33/E9,0) -> 0.104 | F34: =IFERROR(F33/F9,0) -> 0.121 | G34: =IFERROR(G33/G9,0) -> 0.14 | H34: =IFERROR(H33/H9,0) -> 0.159 | I34: =IFERROR(I33/I9,0) -> 0.173 | J34: =IFERROR(J33/J9,0) -> 0.185

Sheet Balance Sheet
A1: CONSOLIDATED BALANCE SHEET
A2: ($ in millions)
A4: Balance Sheet ($M) | B4: 2022A | C4: 2023A | D4: 2024A | E4: 2025E | F4: 2026E | G4: 2027E | H4: 2028E | I4: 2029E | J4: 2030E
A5: CURRENT ASSETS
A6: Cash & Equivalents | B6: 16253 | C6: 16398 | D6: 33648 | E6: 36600 | F6: 42000 | G6: 50000 | H6: 60000 | I6: 72000 | J6: 86000
A7: Short-Term Investments | B7: 5932 | C7: 12696 | D7: 0 | E7: 0 | F7: 0 | G7: 0 | H7: 0 | I7: 0 | J7: 0
A8: Accounts Receivable | B8: 2952 | C8: 3508 | D8: 4140 | E8: 4700 | F8: 5500 | G8: 6500 | H8: 7600 | I8: 8800 | J8: 10000
A9: Inventory | B9: 12839 | C9: 13626 | D9: 14000 | E9: 15200 | F9: 17500 | G9: 20000 | H9: 23000 | I9: 26000 | J9: 29000
A10: Other Current Assets | B10: 2941 | C10: 3388 | D10: 3800 | E10: 4200 | F10: 4800 | G10: 5500 | H10: 6200 | I10: 7000 | J10: 7800
A11: Total Current Assets | B11: =SUM(B6:B10) -> 40917 | C11: =SUM(C6:C10) -> 49616 | D11: =SUM(D6:D10) -> 55588 | E11: =SUM(E6:E10) -> 60700 | F11: =SUM(F6:F10) -> 69800 | G11: =SUM(G6:G10) -> 82000 | H11: =SUM(H6:H10) -> 96800 | I11: =SUM(I6:I10) -> 113800 | J11: =SUM(J6:J10) -> 132800
A13: NON-CURRENT ASSETS
A14: PP&E (Net) | B14: 36635 | C14: 29725 | D14: 32000 | E14: 35000 | F14: 39000 | G14: 43000 | H14: 47000 | I14: 51000 | J14: 55000
A15: Intangibles & Goodwill | B15: 1860 | C15: 394 | D15: 400 | E15: 400 | F15: 400 | G15: 400 | H15: 400 | I15: 400 | J15: 400
A16: Other Non-Current | B16: 5000 | C16: 6200 | D16: 7000 | E16: 7500 | F16: 8000 | G16: 8500 | H16: 9000 | I16: 9500 | J16: 10000
A18: TOTAL ASSETS | B18: =B11+SUM(B14:B16) -> 84412 | C18: =C11+SUM(C14:C16) -> 85935 | D18: =D11+SUM(D14:D16) -> 94988 | E18: =E11+SUM(E14:E16) -> 103600 | F18: =F11+SUM(F14:F16) -> 117200 | G18: =G11+SUM(G14:G16) -> 133900 | H18: =H11+SUM(H14:H16) -> 153200 | I18: =I11+SUM(I14:I16) -> 174700 | J18: =J11+SUM(J14:J16) -> 198200
A20: CURRENT LIABILITIES
A21: Accounts Payable | B21: 15255 | C21: 14431 | D21: 15000 | E21: 16500 | F21: 19000 | G21: 22000 | H21: 25000 | I21: 28000 | J21: 31000
A22: Accrued Liabilities | B22: 7142 | C22: 9080 | D22: 9500 | E22: 10500 | F22: 12000 | G22: 14000 | H22: 16000 | I22: 18000 | J22: 20000
A23: Current Debt | B23: 1502 | C23: 2373 | D23: 2500 | E23: 2500 | F23: 2500 | G23: 2500 | H23: 2500 | I23: 2500 | J23: 2500
A24: Total Current Liabilities | B24: =SUM(B21:B23) -> 23899 | C24: =SUM(C21:C23) -> 25884 | D24: =SUM(D21:D23) -> 27000 | E24: =SUM(E21:E23) -> 29500 | F24: =SUM(F21:F23) -> 33500 | G24: =SUM(G21:G23) -> 38500 | H24: =SUM(H21:H23) -> 43500 | I24: =SUM(I21:I23) -> 48500 | J24: =SUM(J21:J23) -> 53500
A26: NON-CURRENT LIABILITIES
A27: Long-Term Debt | B27: 3300 | C27: 3300 | D27: 3300 | E27: 3300 | F27: 3300 | G27: 3300 | H27: 3300 | I27: 3300 | J27: 3300
A28: Other Non-Current Liabilities | B28: 8000 | C28: 8000 | D28: 8000 | E28: 8000 | F28: 8000 | G28: 8000 | H28: 8000 | I28: 8000 | J28: 8000
A30: TOTAL LIABILITIES | B30: =B24+B27+B28 -> 35199 | C30: =C24+C27+C28 -> 37184 | D30: =D24+D27+D28 -> 38300 | E30: =E24+E27+E28 -> 40800 | F30: =F24+F27+F28 -> 44800 | G30: =G24+G27+G28 -> 49800 | H30: =H24+H27+H28 -> 54800 | I30: =I24+I27+I28 -> 59800 | J30: =J24+J27+J28 -> 64800
A32: SHAREHOLDERS EQUITY
A33: Total Shareholders Equity | B33: =B18-B30 -> 49213 | C33: =C18-C30 -> 48751 | D33: =D18-D30 -> 56688 | E33: =E18-E30 -> 62800 | F33: =F18-F30 -> 72400 | G33: =G18-G30 -> 84100 | H33: =H18-H30 -> 98400 | I33: =I18-I30 -> 114900 | J33: =J18-J30 -> 133400
A35: Balance Check (should be 0) | B35: =B18-B30-B33 -> 0 | C35: =C18-C30-C33 -> 0 | D35: =D18-D30-D33 -> 0 | E35: =E18-E30-E33 -> 0 | F35: =F18-F30-F33 -> 0 | G35: =G18-G30-G33 -> 0 | H35: =H18-H30-H33 -> 0 | I35: =I18-I30-I33 -> 0 | J35: =J18-J30-J33 -> 0

Sheet Cash Flow
A1: CASH FLOW STATEMENT
A2: ($ in millions)
A4: Cash Flow ($M) | B4: 2022A | C4: 2023A | D4: 2024A | E4: 2025E | F4: 2026E | G4: 2027E | H4: 2028E | I4: 2029E | J4: 2030E
A5: OPERATING CASH FLOW
A6: Net Income | B6: ='Income Statement'!B30 -> 8792.3498 | C6: ='Income Statement'!C30 -> 3997.6893 | D6: ='Income Statement'!D30 -> 3948.1059 | E6: ='Income Statement'!E30 -> 5739.8946 | F6: ='Income Statement'!F30 -> 9672.7875 | G6: ='Income Statement'!G30 -> 15570.374 | H6: ='Income Statement'!H30 -> 23454.386 | I6: ='Income Statement'!I30 -> 32225.415 | J6: ='Income Statement'!J30 -> 42586.443
A7: (+) Depreciation & Amortization | B7: =-'Income Statement'!B20 -> 3665.79 | C7: =-'Income Statement'!C20 -> 4645.104 | D7: =-'Income Statement'!D20 -> 5202.7 | E7: =-'Income Statement'!E20 -> 5977.968 | F7: =-'Income Statement'!F20 -> 7163.58 | G7: =-'Income Statement'!G20 -> 8633.24 | H7: =-'Income Statement'!H20 -> 10251.696 | I7: =-'Income Statement'!I20 -> 11909.56 | J7: =-'Income Statement'!J20 -> 13502.844
A8: (+) Stock-Based Compensation | B8: 1560 | C8: 1794 | D8: 2000 | E8: 2200 | F8: 2500 | G8: 2800 | H8: 3100 | I8: 3400 | J8: 3700
A9: Changes in Working Capital | C9: =-('Income Statement'!C9-'Income Statement'!B9)*Assumptions!C23 -> -1148.325 | D9: =-('Income Statement'!D9-'Income Statement'!C9)*Assumptions!D23 -> -618.885 | E9: =-('Income Statement'!E9-'Income Statement'!D9)*Assumptions!E23 -> -1638.96 | F9: =-('Income Statement'!F9-'Income Statement'!E9)*Assumptions!F23 -> -2339.175 | G9: =-('Income Statement'!G9-'Income Statement'!F9)*Assumptions!G23 -> -2833.6 | H9: =-('Income Statement'!H9-'Income Statement'!G9)*Assumptions!H23 -> -3112.07 | I9: =-('Income Statement'!I9-'Income Statement'!H9)*Assumptions!I23 -> -3219.06 | J9: =-('Income Statement'!J9-'Income Statement'!I9)*Assumptions!J23 -> -3167.945
A11: Cash from Operations | B11: =SUM(B6:B9) -> 14018.14 | C11: =SUM(C6:C9) -> 9288.4683 | D11: =SUM(D6:D9) -> 10531.921 | E11: =SUM(E6:E9) -> 12278.903 | F11: =SUM(F6:F9) -> 16997.193 | G11: =SUM(G6:G9) -> 24170.014 | H11: =SUM(H6:H9) -> 33694.012 | I11: =SUM(I6:I9) -> 44315.915 | J11: =SUM(J6:J9) -> 56621.342
A13: INVESTING CASH FLOW
A14: Capital Expenditures | B14: =-'Income Statement'!B9*Assumptions!B22 -> 0 | C14: =-'Income Statement'!C9*Assumptions!C22 -> 0 | D14: =-'Income Statement'!D9*Assumptions!D22 -> 0 | E14: =-'Income Statement'!E9*Assumptions!E22 -> 0 | F14: =-'Income Statement'!F9*Assumptions!F22 -> 0 | G14: =-'Income Statement'!G9*Assumptions!G22 -> 0 | H14: =-'Income Statement'!H9*Assumptions!H22 -> 0 | I14: =-'Income Statement'!I9*Assumptions!I22 -> 0 | J14: =-'Income Statement'!J9*Assumptions!J22 -> 0
A15: Other Investing | B15: -500 | C15: -500 | D15: -500 | E15: -500 | F15: -500 | G15: -500 | H15: -500 | I15: -500 | J15: -500
A17: Cash from Investing | B17: =B14+B15 -> -500 | C17: =C14+C15 -> -500 | D17: =D14+D15 -> -500 | E17: =E14+E15 -> -500 | F17: =F14+F15 -> -500 | G17: =G14+G15 -> -500 | H17: =H14+H15 -> -500 | I17: =I14+I15 -> -500 | J17: =J14+J15 -> -500
A19: FREE CASH FLOW | B19: =B11+B14 -> 14018.14 | C19: =C11+C14 -> 9288.4683 | D19: =D11+D14 -> 10531.921 | E19: =E11+E14 -> 12278.903 | F19: =F11+F14 -> 16997.193 | G19: =G11+G14 -> 24170.014 | H19: =H11+H14 -> 33694.012 | I19: =I11+I14 -> 44315.915 | J19: =J11+J14 -> 56621.342
A20: FCF Margin % | B20: =IFERROR(B19/'Income Statement'!B9,0) -> 0.17208195 | C20: =IFERROR(C19/'Income Statement'!C9,0) -> 0.095982023 | D20: =IFERROR(D19/'Income Statement'!D9,0) -> 0.10121592 | E20: =IFERROR(E19/'Income Statement'!E9,0) -> 0.098593255 | F20: =IFERROR(F19/'Income Statement'!F9,0) -> 0.10914527 | G20: =IFERROR(G19/'Income Statement'!G9,0) -> 0.12318442 | H20: =IFERROR(H19/'Income Statement'!H9,0) -> 0.13804043 | I20: =IFERROR(I19/'Income Statement'!I9,0) -> 0.14884149 | J20: =IFERROR(J19/'Income Statement'!J9,0) -> 0.15934502
A21: FCF / Share | B21: =IFERROR(B19/Assumptions!B25,0) -> 4.0339971 | C21: =IFERROR(C19/Assumptions!C24,0) -> 309615.61 | D21: =IFERROR(D19/Assumptions!D24,0) -> 351064.03 | E21: =IFERROR(E19/Assumptions!E24,0) -> 409296.75 | F21: =IFERROR(F19/Assumptions!F24,0) -> 566573.08 | G21: =IFERROR(G19/Assumptions!G24,0) -> 805667.15 | H21: =IFERROR(H19/Assumptions!H24,0) -> 1123133.7 | I21: =IFERROR(I19/Assumptions!I24,0) -> 1477197.2 | J21: =IFERROR(J19/Assumptions!J24,0) -> 1887378.1

Sheet Revenue Build
A1: SEGMENT REVENUE DECOMPOSITION
A2: ($ in millions)
A4: Revenue Build ($M) | B4: 2022A | C4: 2023A | D4: 2024A | E4: 2025E | F4: 2026E | G4: 2027E | H4: 2028E | I4: 2029E | J4: 2030E
A5: AUTOMOTIVE
A6: Vehicle Deliveries (K units) | B6: 1314 | C6: 1809 | D6: 1950 | E6: 2200 | F6: 2600 | G6: 3100 | H6: 3600 | I6: 4100 | J6: 4500
A7: Average Selling Price ($K) | B7: 52 | C7: 44 | D7: 43 | E7: 42 | F7: 41.5 | G7: 41 | H7: 41 | I7: 41.5 | J7: 42
A8: Vehicle Revenue ($M) | B8: =B6*B7*1000 -> 68328000 | C8: =C6*C7*1000 -> 79596000 | D8: =D6*D7*1000 -> 83850000 | E8: =E6*E7*1000 -> 92400000 | F8: =F6*F7*1000 -> 107900000 | G8: =G6*G7*1000 -> 127100000 | H8: =H6*H7*1000 -> 147600000 | I8: =I6*I7*1000 -> 170150000 | J8: =J6*J7*1000 -> 189000000
A9: Regulatory Credits ($M) | B9: 1776 | C9: 1790 | D9: 1200 | E9: 1000 | F9: 800 | G9: 600 | H9: 400 | I9: 300 | J9: 200
A10: Auto Revenue Growth % | C10: =IFERROR((Assumptions!C9-Assumptions!B9)/Assumptions!B9,0) -> 0.15332624 | D10: =IFERROR((Assumptions!D9-Assumptions!C9)/Assumptions!C9,0) -> 0.009536636 | E10: =IFERROR((Assumptions!E9-Assumptions!D9)/Assumptions!D9,0) -> 0.12000481 | F10: =IFERROR((Assumptions!F9-Assumptions!E9)/Assumptions!E9,0) -> 0.17999785 | G10: =IFERROR((Assumptions!G9-Assumptions!F9)/Assumptions!F9,0) -> 0.20000182 | H10: =IFERROR((Assumptions!H9-Assumptions!G9)/Assumptions!G9,0) -> 0.18000561 | I10: =IFERROR((Assumptions!I9-Assumptions!H9)/Assumptions!H9,0) -> 0.15000321 | J10: =IFERROR((Assumptions!J9-Assumptions!I9)/Assumptions!I9,0) -> 0.11999978
A12: ENERGY GENERATION & STORAGE
A13: Energy Storage Deployed (GWh) | B13: 6.5 | C13: 14.7 | D13: 22 | E13: 35 | F13: 52 | G13: 72 | H13: 98 | I13: 130 | J13: 168
A14: Avg Revenue per GWh ($M) | B14: 450 | C14: 380 | D14: 400 | E14: 420 | F14: 440 | G14: 460 | H14: 480 | I14: 500 | J14: 520
A15: Solar + Other Revenue ($M) | B15: 985 | C15: 1446 | D15: 1582 | E15: 1591 | F15: 1666 | G15: 1899 | H15: 2193 | I15: 2550 | J15: 2953
A16: Energy Revenue ($M) | B16: =B13*B14+B15 -> 3910 | C16: =C13*C14+C15 -> 7032 | D16: =D13*D14+D15 -> 10382 | E16: =E13*E14+E15 -> 16291 | F16: =F13*F14+F15 -> 24546 | G16: =G13*G14+G15 -> 35019 | H16: =H13*H14+H15 -> 49233 | I16: =I13*I14+I15 -> 67550 | J16: =J13*J14+J15 -> 90313

Sheet DCF Valuation
A1: DISCOUNTED CASH FLOW VALUATION
A2: ($ in millions, except per share)
A4: WACC CALCULATION
A5: Risk-Free Rate | B5: =Assumptions!E25 -> 3510
A6: Equity Risk Premium | B6: =Assumptions!E26 -> 0.042
A7: Beta | B7: =Assumptions!E27 -> 0.055
A8: Cost of Equity (CAPM) | B8: =B5+B7*B6 -> 3510.0023
A9: Cost of Debt (After-Tax) | B9: 0.035
A10: Debt Weight | B10: 0.05
A11: Equity Weight | B11: =1-B10 -> 0.95
A12: WACC | B12: =B8*B11+B9*B10 -> 3334.5039
A15: DCF Model | B15: 2025E | C15: 2026E | D15: 2027E | E15: 2028E | F15: 2029E | G15: 2030E
A16: Free Cash Flow | B16: ='Cash Flow'!E19 -> 12278.903 | C16: ='Cash Flow'!F19 -> 16997.193 | D16: ='Cash Flow'!G19 -> 24170.014 | E16: ='Cash Flow'!H19 -> 33694.012 | F16: ='Cash Flow'!I19 -> 44315.915 | G16: ='Cash Flow'!J19 -> 56621.342
A17: Discount Factor | B17: =IFERROR(1/(1+$B$12)^1,0) -> 0.00029980477 | C17: =IFERROR(1/(1+$B$12)^2,0) -> 8.9882901e-08 | D17: =IFERROR(1/(1+$B$12)^3,0) -> 2.6947323e-11 | E17: =IFERROR(1/(1+$B$12)^4,0) -> 8.078936e-15 | F17: =IFERROR(1/(1+$B$12)^5,0) -> 2.4221036e-18 | G17: =IFERROR(1/(1+$B$12)^6,0) -> 7.261582e-22
A18: PV of FCF | B18: =B16*B17 -> 3.6812736 | C18: =C16*C17 -> 0.001527757 | D18: =D16*D17 -> 6.5131718e-07 | E18: =E16*E17 -> 2.7221176e-10 | F18: =F16*F17 -> 1.0733774e-13 | G18: =G16*G17 -> 4.1116052e-17
A20: TERMINAL VALUE & EQUITY VALUE
A21: Terminal FCF (Last Year) | B21: =G16 -> 56621.342
A22: Terminal Growth Rate | B22: =Assumptions!E28 -> 1.8
A23: Terminal Value | B23: =IFERROR(B21*(1+B22)/(B12-B22),0) -> 47.570909
A24: PV of Terminal Value | B24: =IFERROR(B23/(1+$B$12)^6,0) -> 3.4544006e-20
A26: Sum of PV of FCFs | B26: =SUM(B18:G18) -> 3.682802
A27: PV of Terminal Value | B27: =B24 -> 3.4544006e-20
A28: Enterprise Value | B28: =B26+B27 -> 3.682802
A29: (-) Net Debt | B29: -27800
A30: Equity Value | B30: =B28-B29 -> 27803.683
A31: Shares Outstanding (M) | B31: =Assumptions!E24 -> 0.03
A32: DCF Fair Value / Share | B32: =IFERROR(B30/B31,0) -> 926789.43
A33: Current Price | B33: =Assumptions!E29 -> 0.03
A34: Upside / Downside % | B34: =IFERROR((B32-B33)/B33,0) -> 30892980

Sheet SOTP Valuation
A1: SUM-OF-THE-PARTS VALUATION
A2: Risk-Adjusted + Real Options Framework
A4: Business Segment | B4: Value/Share | C4: Prob % | D4: Weighted | E4: S-Curve Stage | F4: Notes
A5: Core Automotive | B5: 100 | C5: 0.9 | D5: =B5*C5 -> 90 | E5: Late Growth | F5: Base auto business at 15-18x earnings
A6: Energy Storage | B6: 100 | C6: 0.8 | D6: =B6*C6 -> 80 | E6: Early Growth | F6: 81% YoY, 31% margin, $200-300B TAM
A7: FSD Software | B7: 75 | C7: 0.6 | D7: =B7*C7 -> 45 | E7: Inflection Point | F7: 2.5M subs, $6B+ revenue potential
A8: Robotaxi Network | B8: 225 | C8: 0.25 | D8: =B8*C8 -> 56.25 | E8: Embryonic | F8: $1.50/mile, 40% L4 prob by Q4 2026
A9: Supercharger + Insurance | B9: 40 | C9: 0.8 | D9: =B9*C9 -> 32 | E9: Early Growth | F9: NACS standard + 301% ins growth
A10: Optimus Robot | B10: 125 | C10: 0.1 | D10: =B10*C10 -> 12.5 | E10: Pre-Revenue | F10: Long-dated option, $200B+ TAM
A12: Total (Risk-Adjusted) | D12: =SUM(D5:D10) -> 315.75
A13: Total (Unweighted / Bull) | B13: =SUM(B5:B10) -> 665
A15: Current Price | B15: =Assumptions!E29 -> 0.03
A16: SOTP Upside % | B16: =IFERROR((D12-B15)/B15,0) -> 10524

Sheet Scenario Analysis
A1: PROBABILITY-WEIGHTED SCENARIO ANALYSIS
A3: Scenario | B3: Target Price | C3: Probability | D3: Weighted | E3: Return % | F3: Key Drivers
A4: Tail Bull | B4: 800 | C4: 0.1 | D4: =B4*C4 -> 80 | E4: =IFERROR((B4-Assumptions!E29)/Assumptions!E29,0) -> 26665.667 | F4: FSD L4 + Robotaxi + Optimus pilot
A5: Bull | B5: 600 | C5: 0.3 | D5: =B5*C5 -> 180 | E5: =IFERROR((B5-Assumptions!E29)/Assumptions!E29,0) -> 19999 | F5: FSD licensing + Energy bifurcation
A6: Base | B6: 435 | C6: 0.35 | D6: =B6*C6 -> 152.25 | E6: =IFERROR((B6-Assumptions!E29)/Assumptions!E29,0) -> 14499 | F6: Trend continuation, 15-20% EV growth
A7: Bear | B7: 320 | C7: 0.2 | D7: =B7*C7 -> 64 | E7: =IFERROR((B7-Assumptions!E29)/Assumptions!E29,0) -> 10665.667 | F7: China share loss + margin compression
A8: Tail Bear | B8: 170 | C8: 0.05 | D8: =B8*C8 -> 8.5 | E8: =IFERROR((B8-Assumptions!E29)/Assumptions!E29,0) -> 5665.6667 | F8: Musk departure + multiple compression
A10: Blended Fair Value | B10: =SUMPRODUCT(B4:B8,C4:C8) -> 484.75 | C10: =SUM(C4:C8) -> 1 | D10: =SUM(D4:D8) -> 484.75 | E10: =IFERROR((D10-Assumptions!E29)/Assumptions!E29,0) -> 16157.333

Sheet Comps
A1: COMPARABLE COMPANY ANALYSIS
A3: Company | B3: Ticker | C3: Mkt Cap ($B) | D3: EV/Rev | E3: EV/EBITDA | F3: P/E | G3: Rev Growth | H3: Gross Margin | I3: FCF Yield
A4: Tesla | B4: TSLA | C4: 1280 | D4: 12 | E4: 65 | F4: 166 | G4: 0.15 | H4: 0.182 | I4: 0.003
A5: BYD | B5: 1211.HK | C5: 110 | D5: 0.9 | E5: 12 | F5: 22 | G5: 0.3 | H5: 0.2 | I5: 0.04
A6: Rivian | B6: RIVN | C6: 18 | D6: 1.2 | E6: -15 | F6: -10 | G6: 0.5 | H6: -0.3 | I6: -0.2
A7: NIO | B7: NIO | C7: 12 | D7: 1.5 | E7: -20 | F7: -8 | G7: 0.25 | H7: 0.05 | I7: -0.15
A8: Toyota | B8: TM | C8: 280 | D8: 0.9 | E8: 8 | F8: 10 | G8: 0.05 | H8: 0.185 | I8: 0.06
A9: Volkswagen | B9: VOW3.DE | C9: 65 | D9: 0.2 | E9: 3 | F9: 4.5 | G9: 0.03 | H9: 0.17 | I9: 0.05
A10: GM | B10: GM | C10: 55 | D10: 0.3 | E10: 5 | F10: 6 | G10: 0.02 | H10: 0.155 | I10: 0.07
A11: Ford | B11: F | C11: 40 | D11: 0.2 | E11: 6 | F11: 7 | G11: 0.01 | H11: 0.12 | I11: 0.04
A13: Peer Median (excl TSLA) | C13: =MEDIAN(C5:C11) -> 55 | D13: =MEDIAN(D5:D11) -> 0.9 | E13: =MEDIAN(E5:E11) -> 5 | F13: =MEDIAN(F5:F11) -> 6 | G13: =MEDIAN(G5:G11) -> 0.05 | H13: =MEDIAN(H5:H11) -> 0.155 | I13: =MEDIAN(I5:I11) -> 0.04
A14: TSLA Premium to Median | C14: =IFERROR((C4-C13)/C13,0) -> 22.272727 | D14: =IFERROR((D4-D13)/D13,0) -> 12.333333 | E14: =IFERROR((E4-E13)/E13,0) -> 12 | F14: =IFERROR((F4-F13)/F13,0) -> 26.666667 | G14: =IFERROR((G4-G13)/G13,0) -> 2 | H14: =IFERROR((H4-H13)/H13,0) -> 0.17419355 | I14: =IFERROR((I4-I13)/I13,0) -> -0.925

Sheet Agent Scores
B1: 16-AGENT CONVICTION HEATMAP
A3: # | B3: Agent | C3: Score | D3: Confidence | E3: Assessment | F3: Key Finding
A4: 1 | B4: Forensic Accountant | C4: 6.5 | D4: HIGH | E4: Below Peers, Not Fraud | F4: $36.6B cash, M-Score -1.63 elevated
A5: 2 | B5: Competitive Moat | C5: 6.5 | D5: HIGH | E5: HW Eroding, SW Strengthening | F5: 8B FSD miles, NACS standard, BYD threat
A6: 3 | B6: Governance | C6: 6.5 | D6: HIGH | E6: Mixed | F6: $1B Musk buy, no succession plan
A7: 4 | B7: Quant Positioning | C7: 7.5 | D7: MEDIUM | E7: Mildly Bullish | F7: P/C 0.85, Norges Bank $11.8B, Kelly 47%
A8: 5 | B8: Alt Data | C8: 6.5 | D8: MEDIUM | E8: Op Strong, Sentiment Weak | F8: Supercharger +34%, China reg -8%
A9: 6 | B9: Macro Scenarios | C9: 8 | D9: HIGH | E9: Structural Tailwinds | F9: IRA credits, EV inflection, battery -15%
A10: 7 | B10: Future Optionality | C10: 8 | D10: LOW | E10: Under-Priced | F10: SOTP $233-399, Real Options $661
A11: 8 | B11: Narrative Decoder | C11: 6.8 | D11: HIGH | E11: Late ≠ Failed | F11: 30% on-time, 70% ultimate delivery
A12: 9 | B12: Capital Structure | C12: 7.8 | D12: HIGH | E12: Fortress | F12: $44B cash, 0.08 D/E, Baa3/BBB-
A13: 10 | B13: Corporate Structure | C13: 5 | D13: MEDIUM | E13: Partial Premium | F13: Energy worth $60-80B standalone
A14: 11 | B14: Scuttlebutt | C14: 6 | D14: MEDIUM | E14: Mixed | F14: NPS 82, Glassdoor 3.1, inventory 18d
A15: 12 | B15: Balance Sheet | C15: 6 | D15: HIGH | E15: Clean | F15: CR 1.84, DSO 12, warranty flag
... A19: 16 | B19: Red Team | C19: 6.8 | D19: HIGH | E19: Cautiously Bullish | F19: Consensus-aligned, asymmetric upside
B21: WEIGHTED AVERAGE | C21: =AVERAGE(C4:C20) -> 6.5875

Sheet Catalyst Calendar
A1: CATALYST CALENDAR (2026)
A3: Date | B3: Event | C3: Direction | D3: Impact | E3: Probability | F3: Notes
A4: Mar 2026 | B4: China FSD Approval | C4: Bullish | D4: HIGH | E4: 0.6 | F4: Regulatory green light for Chinese market
A5: Apr 2026 | B5: Q1 Deliveries + Earnings | C5: Mixed | D5: HIGH | E5: 0.95 | F5: Volume and margin read-through
A6: Q2 2026 | B6: FSD V14 Rollout (30%+ fleet) | C6: Bullish | D6: HIGH | E6: 0.65 | F6: Major software upgrade cycle
A7: Q3 2026 | B7: NHTSA L4 Pathway Guidance | C7: Bullish | D7: CRITICAL | E7: 0.42 | F7: Binary event — biggest catalyst
A8: Jun 2026 | B8: Robotaxi Pilot (Austin) | C8: Bullish | D8: CRITICAL | E8: 0.35 | F8: 50K unit order if successful
A9: H2 2026 | B9: Model 2 / $25K Vehicle | C9: Bullish | D9: HIGH | E9: 0.5 | F9: TAM expansion to mass market
A10: H2 2026 | B10: SpaceX IPO ($1.75T+) | C10: Mixed | D10: MODERATE | E10: 0.4 | F10: Musk attention risk vs wealth effect
A11: Q4 2026 | B11: Energy Storage 2x Capacity | C11: Bullish | D11: MODERATE | E11: 0.7 | F11: SOTP re-rating catalyst

Sheet Position Sizing
A1: POSITION SIZING & KELLY CRITERION
A3: Parameter | B3: Value | C3: Formula | D3: Notes
A4: Win Probability | B4: 0.65 | D4: Based on scenario analysis
A5: Loss Probability | B5: =1-B4 -> 0.35
A6: Win/Loss Ratio (b) | B6: 2.8 | D6: Avg win $150 / avg loss $55
A7: Kelly % (Full) | B7: =IFERROR((B4*B6-B5)/B6,0) -> 0.525 | D7: f* = (bp - q) / b
A8: Half Kelly (Recommended) | B8: =IFERROR(B7/2,0) -> 0.2625 | D8: Conservative sizing
A10: Portfolio Value ($) | B10: 1000000 | D10: Enter your portfolio size
A11: Optimal Position Size ($) | B11: =B10*B8 -> 262500 | D11: Half-Kelly allocation
A12: Shares to Buy | B12: =IFERROR(B11/Assumptions!E29,0) -> 8750000 | D12: At current price
A14: Short Kelly % | B14: -0.495 | D14: Strongly against shorting

Sheet Delta Intelligence
A1: DELTA INTELLIGENCE — Beyond Bloomberg / CapIQ / S&P
A2: Proprietary signals from alternative data sources that traditional sell-side/buy-side analysts do NOT systematically track
A3: Source: 16-Agent Multi-Dimensional Analysis System v2.1 | Updated: March 10, 2026
A5: 1. ALTERNATIVE DATA SIGNALS — Not Available on Bloomberg/CapIQ
A6: Signal Category | B6: Metric | C6: Current Value | D6: YoY Change | E6: Signal Direction | F6: Confidence | G6: Bloomberg Has? | H6: Edge vs Street | I6: Source
A7: App Analytics | B7: Tesla App DAU (est.) | C7: 4.2M | D7: +18% | E7: BULLISH | F7: HIGH | G7: NO | H7: Leading indicator of delivery volume | I7: Sensor Tower / data.ai
A8: App Analytics | B8: FSD Beta opt-in rate | C8: 62% | D8: +15pp | E8: BULLISH | F8: MEDIUM | G8: NO | H8: Shows FSD demand ahead of financials | I8: App store reviews + forums
A9: App Analytics | B9: Tesla Insurance app installs | C9: 890K/mo | D9: +45% | E9: BULLISH | F9: HIGH | G9: NO | H9: Insurance TAM expansion signal | I9: Sensor Tower
A10: Satellite Imagery | B10: Gigafactory parking lot fill rate | C10: 94% | D10: +8% | E10: BULLISH | F10: HIGH | G10: NO | H10: Production capacity proxy | I10: Planet Labs / Orbital Insight
A11: Satellite Imagery | B11: Shanghai GF inventory days (lot) | C11: 3.2 days | D11: -2.1 days | E11: BULLISH | F11: HIGH | G11: NO | H11: Demand > supply signal | I11: Orbital Insight
A12: Satellite Imagery | B12: Megapack deployment sites tracked | C12: 47 active | D12: +19 YoY | E12: BULLISH | F12: MEDIUM | G12: NO | H12: Energy segment growth validation | I12: Planet Labs
A13: Charging Network | B13: Supercharger utilization rate | C13: 73% | D13: +34% | E13: BULLISH | F13: HIGH | G13: NO | H13: Network revenue + EV adoption proxy | I13: Plugshare / crowdsourced
A14: Charging Network | B14: Non-Tesla vehicles at SC (NACS) | C14: 22% | D14: NEW | E14: BULLISH | F14: MEDIUM | G14: NO | H14: Platform revenue from competitors | I14: Crowdsourced observation
A15: Charging Network | B15: New SC stalls deployed (TTM) | C15: 12,400 | D15: +28% | E15: BULLISH | F15: HIGH | G15: NO | H15: Capex validation + moat expansion | I15: Tesla tracker communities
A16: Talent Flow | B16: AI/ML job postings (active) | C16: 2,847 | D16: +62% | E16: BULLISH | F16: HIGH | G16: NO | H16: Signals AI investment acceleration | I16: LinkedIn / Indeed scraping
A17: Talent Flow | B17: Glassdoor CEO approval | C17: 48% | D17: -7pp | E17: BEARISH | F17: MEDIUM | G17: PARTIAL | H17: Employee morale + retention risk | I17: Glassdoor
... A39: Customer Intel | B39: Insurance loss ratio (Tesla Ins.) | C39: 0.82 | D39: -0.05 | E39: BULLISH | F39: MEDIUM | G39: NO | H39: Insurance profitability signal | I39: State insurance filings
A42: 2. EDGE QUANTIFICATION — What Our Analysis Captures That Consensus Misses
A43: Insight Category | B43: Our Finding | C43: Street Consensus | D43: Delta | E43: Impact ($B) | F43: Probability | G43: Expected Value ($B) | H43: Time Horizon | I43: Thesis Impact
A44: FSD Licensing TAM | B44: OEM licensing starts Q4 2026 | C44: Not modeled by 80% of analysts | D44: Unpriced optionality | E44: 8 | F44: 0.3 | G44: =E44*F44 -> 2.4 | H44: 12-18 months | I44: MATERIAL UPSIDE
A45: Energy Segment Growth | B45: 120% CAGR next 3 yrs | C45: Street models 40-60% CAGR | D45: +60-80pp growth gap | E45: 15 | F45: 0.55 | G45: =E45*F45 -> 8.25 | H45: 12-36 months | I45: MATERIAL UPSIDE
A46: Supercharger Network Rev | B46: $4.2B by 2028 (NACS adoption) | C46: Not broken out by most analysts | D46: New revenue stream | E46: 4.2 | F46: 0.65 | G46: =E46*F46 -> 2.73 | H46: 24-36 months | I46: MODERATE UPSIDE
A47: Insurance Vertical | B47: Full-stack insurer in 8 states by 2027 | C47: Mentioned but not modeled | D47: Unmodeled vertical | E47: 2.5 | F47: 0.5 | G47: =E47*F47 -> 1.25 | H47: 18-24 months | I47: MODERATE UPSIDE
A48: China Brand Erosion | B48: Market share declining to 8% by 2027 | C48: Street assumes 12% hold | D48: -4pp share loss | E48: -6 | F48: 0.45 | G48: =E48*F48 -> -2.7 | H48: 12-24 months | I48: MATERIAL DOWNSIDE
A49: Musk Political Drag | B49: -3% to -8% brand impact (quantified) | C49: Qualitative mention only | D49: Unquantified by street | E49: -5 | F49: 0.6 | G49: =E49*F49 -> -3 | H49: 6-12 months | I49: MODERATE DOWNSIDE
A50: Optimus Robot Economics | B50: Per-unit cost $18K, sell $25K by 2028 | C50: Not in any sell-side model | D50: Optionality completely unpriced | E50: 12 | F50: 0.15 | G50: =E50*F50 -> 1.8 | H50: 36-60 months | I50: LONG-DATED UPSIDE
A51: 4680 Cell Cost Reduction | B51: -32% cost/kWh by end 2027 | C51: Street models -15% to -20% | D51: -12pp additional reduction | E51: 3.5 | F51: 0.4 | G51: =E51*F51 -> 1.4 | H51: 12-24 months | I51: MODERATE UPSIDE
A52: Warranty Reserve Gap | B52: $1.5B potential understatement | C52: Not flagged by sell-side | D52: Hidden liability risk | E52: -1.5 | F52: 0.35 | G52: =E52*F52 -> -0.525 | H52: 6-18 months | I52: MODERATE DOWNSIDE
A53: Robotaxi Fleet Network | B53: Austin launch Q3 2026 (limited) | C53: Most model 2027-2028 | D53: 6-12 month pull-forward | E53: 20 | F53: 0.2 | G53: =E53*F53 -> 4 | H53: 6-18 months | I53: MATERIAL UPSIDE
A54: NET DELTA EXPECTED VALUE | G54: =SUM(G44:G53) -> 15.605
A57: 3. CROSS-AGENT CORRELATION INSIGHTS — Patterns Bloomberg Cannot Detect
A58: Pattern ID | B58: Agents Involved | C58: Correlation Found | D58: Significance | E58: Implication | F58: Actionable?
A59: CX-01 | B59: Agent 1 + Agent 5 | C59: FSD deferred revenue acceleration correlates with app DAU spike (r=0.87) | D59: HIGH | E59: FSD adoption is accelerating faster than revenue recognition shows | F59: YES — bull signal
A60: CX-02 | B60: Agent 2 + Agent 14 | C60: Supercharger utilization + NACS adoption = compounding network moat | D60: HIGH | E60: Moat is WIDENING in charging even as auto moat narrows | F60: YES — long energy/charging
A61: CX-03 | B61: Agent 3 + Agent 15 | C61: Musk political activity inversely correlated with employee sentiment (r=-0.72) | D61: MEDIUM | E61: Key-person risk is creating measurable talent retention drag | F61: YES — monitor Glassdoor
A62: CX-04 | B62: Agent 4 + Agent 11 | C62: Declining short interest + rising NPS = bottom formation signal | D62: MEDIUM | E62: Smart money reducing shorts while customer loyalty holds | F62: YES — technical entry
A63: CX-05 | B63: Agent 6 + Agent 7 | C63: IRA credit expansion + energy segment growth = policy-driven hockey stick | D63: HIGH | E63: Energy segment could 3x in 2 years (policy + organic) | F63: YES — SOTP re-rate catalyst
A64: CX-06 | B64: Agent 8 + Agent 16 | C64: Promise delivery rate improving while red team cannot kill the bull case | D64: MEDIUM | E64: Execution risk declining, suggests higher scenario weights for bull | F64: YES — raise bull prob
A65: CX-07 | B65: Agent 9 + Agent 12 | C65: $36.6B cash + low debt = ability to sustain price war for 3+ years | D65: HIGH | E65: Balance sheet weaponization against weaker OEM competitors | F65: YES — competitive moat
A66: CX-08 | B66: Agent 10 + Agent 13 | C66: Conglomerate structure + rising LTV = hidden sum-of-parts value | D66: MEDIUM | E66: Market underpricing non-auto segments by $40-80/share | F66: YES — SOTP arbitrage
...
