Workbook

Sheet Cover
A1: NETFLIX INC (NFLX) - INVESTMENT THESIS
A3: Ticker | B3: NFLX
A4: Company | B4: Netflix Inc
A5: Current Price | B5: $94.96
A7: Market Cap ($B) | B7: $404.0
A8: 52-Week Range | B8: $81 - $135
A9: Shares Outstanding (M) | B9: 425.5
A11: VALUATION SUMMARY
A12: DCF Fair Value | B12: =Assumptions!B$30
A13: SOTP Fair Value | B13: =SOTP!B$15
A14: Blended Fair Value | B14: $109.00
A15: Current Price | B15: $94.96
A16: Upside/(Downside) | B16: 14.8%
A18: INVESTMENT METRICS
A19: Conviction Score | B19: 7.1 | C19: /10
A20: Risk/Reward Profile | B20: Favorable
A21: Variant View | B21: NEUTRAL
A23: REPORT DETAILS
A24: Report Date | B24: March 15, 2026
A25: Analyst | B25: Hedge Fund Analysis
A27: COLOR LEGEND
A28: Blue Font | B28: Hardcoded Inputs/Assumptions
A29: Black Font | B29: Formula-Driven Values
A30: Green Font | B30: Cross-Sheet References
A31: Yellow Highlight | B31: Key Assumptions Needing Attention
A33: DISCLOSURES
A34: This analysis is for illustrative purposes only.
A35: Not investment advice. Do own due diligence.
A36: DETAILED INVESTMENT CASE
A38: Key Bull Thesis Points
A39: 1. Ad Tier Monetization | B39: Unpriced upside | C39: $4B+ revenue by 2026
A40: 2. ARPU Expansion | B40: Pricing power | C40: +$1.50 per sub by 2030
A41: 3. International Growth | B41: 50%+ subs growth | C41: Emerging market expansion
A42: 4. FCF Generation | B42: Fortress balance sheet | C42: $15B+ annual FCF
A43: 5. Content Moat | B43: Exclusive franchises | C43: Squid Game, Wednesday S2+
A45: Key Bear Thesis Points
A46: 1. Churn Acceleration | B46: Market saturation | C46: UCAN/EMEA maturing
A47: 2. Content Costs | B47: Inflation pressure | C47: $22B+ annual spend
A48: 3. Competitive Intensity | B48: Disney, Amazon, Apple | C48: Winner-take-most dynamic
A49: 4. Regulatory Risk | B49: France, EU, China | C49: $500M-$2B downside
...

Sheet Assumptions
A1: Metric | B1: 2021A | C1: 2022A | D1: 2023A | E1: 2024A | F1: 2025A | G1: 2026E | H1: 2027E | I1: 2028E | J1: 2029E | K1: 2030E
A2: Revenue Growth % | B2: 16 | C2: 10.2 | D2: 12.8 | E2: 15.3 | F2: 12 | G2: 14.5 | H2: 13 | I2: 11.5 | J2: 10 | K2: 9
A3: Subscribers (M) | B3: 222 | C3: 231 | D3: 260 | E3: 302 | F3: 325 | G3: 350 | H3: 375 | I3: 400 | J3: 420 | K3: 440
A4: ARPU ($) | B4: 11.02 | C4: 11.31 | D4: 11.5 | E4: 11.6 | F4: 11.7 | G4: 12.1 | H4: 12.6 | I4: 13.2 | J4: 13.8 | K4: 14.4
A5: Content Spend ($B) | B5: 12.2 | C5: 13 | D5: 14.5 | E5: 16 | F5: 17 | G5: 18.5 | H5: 20 | I5: 21.5 | J5: 22.5 | K5: 23.5
A6: Operating Margin % | B6: 20.9 | C6: 18.3 | D6: 21 | E6: 26.7 | F6: 28.1 | G6: 29.5 | H6: 31 | I6: 32 | J6: 33 | K6: 34
A7: CapEx ($B) | B7: 0.5 | C7: 0.5 | D7: 0.5 | E7: 0.6 | F7: 0.7 | G7: 0.8 | H7: 0.9 | I7: 1 | J7: 1.1 | K7: 1.2
A8: Tax Rate % | B8: 15 | C8: 15 | D8: 16 | E8: 17 | F8: 18 | G8: 19 | H8: 19 | I8: 20 | J8: 20 | K8: 20
A9: SBC ($B) | B9: 0.8 | C9: 0.9 | D9: 1 | E9: 1 | F9: 1.1 | G9: 1.2 | H9: 1.3 | I9: 1.4 | J9: 1.5 | K9: 1.6
A10: D&A ($B) | B10: 12 | C10: 12.5 | D10: 13 | E10: 14.2 | F10: 14.8 | G10: 15.5 | H10: 16 | I10: 16.5 | J10: 17 | K10: 17.5
A11: Ad Revenue ($B) | B11: 0 | C11: 0 | D11: 0.5 | E11: 1.5 | F11: 2.4 | G11: 4 | H11: 5.5 | I11: 7 | J11: 8.5 | K11: 10
A13: WACC COMPONENTS
A14: Risk-Free Rate % | B14: 4.3 | C14: 4.3 | D14: 4.3 | E14: 4.3 | F14: 4.3 | G14: 4.3 | H14: 4.3 | I14: 4.3 | J14: 4.3 | K14: 4.3
A15: Equity Risk Premium % | B15: 5.5 | C15: 5.5 | D15: 5.5 | E15: 5.5 | F15: 5.5 | G15: 5.5 | H15: 5.5 | I15: 5.5 | J15: 5.5 | K15: 5.5
A16: Beta | B16: 1.15 | C16: 1.15 | D16: 1.15 | E16: 1.15 | F16: 1.15 | G16: 1.15 | H16: 1.15 | I16: 1.15 | J16: 1.15 | K16: 1.15
A17: Cost of Equity % | B17: 10.6 | C17: 10.6 | D17: 10.6 | E17: 10.6 | F17: 10.6 | G17: 10.6 | H17: 10.6 | I17: 10.6 | J17: 10.6 | K17: 10.6
A18: Cost of Debt % | B18: 4.5 | C18: 4.5 | D18: 4.5 | E18: 4.5 | F18: 4.5 | G18: 4.5 | H18: 4.5 | I18: 4.5 | J18: 4.5 | K18: 4.5
A19: Tax Shield % | B19: 81 | C19: 81 | D19: 84 | E19: 83 | F19: 82 | G19: 81 | H19: 81 | I19: 80 | J19: 80 | K19: 80
A20: WACC % | B20: 9.2 | C20: 9.2 | D20: 9.2 | E20: 9.2 | F20: 9.2 | G20: 9.2 | H20: 9.2 | I20: 9.2 | J20: 9.2 | K20: 9.2
A21: Terminal Growth Rate % | B21: 3 | C21: 3 | D21: 3 | E21: 3 | F21: 3 | G21: 3 | H21: 3 | I21: 3 | J21: 3 | K21: 3
A23: REGIONAL ASSUMPTIONS
A24: UCAN Revenue Mix % | B24: 45 | C24: 45 | D24: 45 | E24: 45 | F24: 45 | G24: 44 | H24: 43 | I24: 42 | J24: 41 | K24: 40
A25: EMEA Revenue Mix % | B25: 30 | C25: 30 | D25: 30 | E25: 30 | F25: 30 | G25: 31 | H25: 32 | I25: 33 | J25: 34 | K25: 35
A26: APAC Revenue Mix % | B26: 18 | C26: 18 | D26: 18 | E26: 18 | F26: 18 | G26: 19 | H26: 20 | I26: 21 | J26: 22 | K26: 23
A27: LATAM Revenue Mix % | B27: 7 | C27: 7 | D27: 7 | E27: 7 | F27: 7 | G27: 6 | H27: 5 | I27: 4 | J27: 3 | K27: 2
A29: CONTENT METRICS
A30: Originals as % of slate | B30: 55 | C30: 60 | D30: 63 | E30: 65 | F30: 67 | G30: 70 | H30: 72 | I30: 74 | J30: 75 | K30: 76
A31: Licensed as % of slate | B31: 45 | C31: 40 | D31: 37 | E31: 35 | F31: 33 | G31: 30 | H31: 28 | I31: 26 | J31: 25 | K31: 24
A32: Content library titles | B32: 3500 | C32: 3800 | D32: 4100 | E32: 4500 | F32: 5000 | G32: 5500 | H32: 6000 | I32: 6500 | J32: 7000 | K32: 7500
A33: Games released/year | B33: 15 | C33: 20 | D33: 25 | E33: 30 | F33: 35 | G33: 40 | H33: 45 | I33: 50 | J33: 55 | K33: 60

Sheet Income Statement
A1: Metric | B1: 2021A | C1: 2022A | D1: 2023A | E1: 2024A | F1: 2025A | G1: 2026E | H1: 2027E | I1: 2028E | J1: 2029E | K1: 2030E
A2: Subscription Revenue | B2: =Assumptions!B3*Assumptions!B4*12 | C2: =Assumptions!C3*Assumptions!C4*12 | D2: =Assumptions!D3*Assumptions!D4*12 | E2: =Assumptions!E3*Assumptions!E4*12 | F2: =Assumptions!F3*Assumptions!F4*12 | G2: =Assumptions!G3*Assumptions!G4*12 | H2: =Assumptions!H3*Assumptions!H4*12 | I2: =Assumptions!I3*Assumptions!I4*12 | ... K2: =Assumptions!K3*Assumptions!K4*12
A3: Advertising Revenue | B3: =Assumptions!B10 | C3: =Assumptions!C10 | D3: =Assumptions!D10 | E3: =Assumptions!E10 | F3: =Assumptions!F10 | G3: =Assumptions!G10 | H3: =Assumptions!H10 | I3: =Assumptions!I10 | ... K3: =Assumptions!K10
A4: Total Revenue | B4: =B2+B3 | C4: =C2+C3 | D4: =D2+D3 | E4: =E2+E3 | F4: =F2+F3 | G4: =G2+G3 | H4: =H2+H3 | I4: =I2+I3 | ... K4: =K2+K3
A5: Cost of Revenue | B5: =B4*0.30 | C5: =C4*0.30 | D5: =D4*0.30 | E5: =E4*0.30 | F5: =F4*0.30 | G5: =G4*0.30 | H5: =H4*0.30 | I5: =I4*0.30 | ... K5: =K4*0.30
A6: Gross Profit | B6: =B4-B5 | C6: =C4-C5 | D6: =D4-D5 | E6: =E4-E5 | F6: =F4-F5 | G6: =G4-G5 | H6: =H4-H5 | I6: =I4-I5 | ... K6: =K4-K5
A7: Gross Margin % | B7: =IFERROR(B6/B4,0) | C7: =IFERROR(C6/C4,0) | D7: =IFERROR(D6/D4,0) | E7: =IFERROR(E6/E4,0) | F7: =IFERROR(F6/F4,0) | G7: =IFERROR(G6/G4,0) | H7: =IFERROR(H6/H4,0) | I7: =IFERROR(I6/I4,0) | ... K7: =IFERROR(K6/K4,0)
A9: R&D Expense | B9: =B4*0.035 | C9: =C4*0.035 | D9: =D4*0.035 | E9: =E4*0.035 | F9: =F4*0.035 | G9: =G4*0.035 | H9: =H4*0.035 | I9: =I4*0.035 | ... K9: =K4*0.035
A10: Sales & Marketing | B10: =B4*0.08 | C10: =C4*0.08 | D10: =D4*0.08 | E10: =E4*0.08 | F10: =F4*0.08 | G10: =G4*0.08 | H10: =H4*0.08 | I10: =I4*0.08 | ... K10: =K4*0.08
A11: G&A Expense | B11: =B4*0.04 | C11: =C4*0.04 | D11: =D4*0.04 | E11: =E4*0.04 | F11: =F4*0.04 | G11: =G4*0.04 | H11: =H4*0.04 | I11: =I4*0.04 | ... K11: =K4*0.04
A12: Total OpEx | B12: =B9+B10+B11 | C12: =C9+C10+C11 | D12: =D9+D10+D11 | E12: =E9+E10+E11 | F12: =F9+F10+F11 | G12: =G9+G10+G11 | H12: =H9+H10+H11 | I12: =I9+I10+I11 | ... K12: =K9+K10+K11
A14: Operating Income | B14: =B6-B12 | C14: =C6-C12 | D14: =D6-D12 | E14: =E6-E12 | F14: =F6-F12 | G14: =G6-G12 | H14: =H6-H12 | I14: =I6-I12 | ... K14: =K6-K12
A15: Operating Margin % | B15: =IFERROR(B14/B4,0) | C15: =IFERROR(C14/C4,0) | D15: =IFERROR(D14/D4,0) | E15: =IFERROR(E14/E4,0) | F15: =IFERROR(F14/F4,0) | G15: =IFERROR(G14/G4,0) | H15: =IFERROR(H14/H4,0) | I15: =IFERROR(I14/I4,0) | ... K15: =IFERROR(K14/K4,0)
A16: Interest Expense | B16: =-500 | C16: =-500 | D16: =-500 | E16: =-500 | F16: =-500 | G16: =-500 | H16: =-500 | I16: =-500 | ... K16: =-500
A17: Other Income | B17: =200 | C17: =200 | D17: =200 | E17: =200 | F17: =200 | G17: =200 | H17: =200 | I17: =200 | ... K17: =200
A19: Pre-Tax Income | B19: =B14+B16+B17 | C19: =C14+C16+C17 | D19: =D14+D16+D17 | E19: =E14+E16+E17 | F19: =F14+F16+F17 | G19: =G14+G16+G17 | H19: =H14+H16+H17 | I19: =I14+I16+I17 | ... K19: =K14+K16+K17
A20: Tax Expense | B20: =B19*Assumptions!B7 | C20: =C19*Assumptions!C7 | D20: =D19*Assumptions!D7 | E20: =E19*Assumptions!E7 | F20: =F19*Assumptions!F7 | G20: =G19*Assumptions!G7 | H20: =H19*Assumptions!H7 | I20: =I19*Assumptions!I7 | ... K20: =K19*Assumptions!K7
A21: Net Income | B21: =B19-B20 | C21: =C19-C20 | D21: =D19-D20 | E21: =E19-E20 | F21: =F19-F20 | G21: =G19-G20 | H21: =H19-H20 | I21: =I19-I20 | ... K21: =K19-K20
A23: Shares Outstanding (M) | B23: =425.5 | C23: =425.5 | D23: =425.5 | E23: =425.5 | F23: =425.5 | G23: =425.5 | H23: =425.5 | I23: =425.5 | ... K23: =425.5
A24: EPS | B24: =IFERROR(B21/B23,0) | C24: =IFERROR(C21/C23,0) | D24: =IFERROR(D21/D23,0) | E24: =IFERROR(E21/E23,0) | F24: =IFERROR(F21/F23,0) | G24: =IFERROR(G21/G23,0) | H24: =IFERROR(H21/H23,0) | I24: =IFERROR(I21/I23,0) | ... K24: =IFERROR(K21/K23,0)
A26: EBITDA | B26: =B14+Assumptions!B9 | C26: =C14+Assumptions!C9 | D26: =D14+Assumptions!D9 | E26: =E14+Assumptions!E9 | F26: =F14+Assumptions!F9 | G26: =G14+Assumptions!G9 | H26: =H14+Assumptions!H9 | I26: =I14+Assumptions!I9 | ... K26: =K14+Assumptions!K9
A27: EBITDA Margin % | B27: =IFERROR(B26/B4,0) | C27: =IFERROR(C26/C4,0) | D27: =IFERROR(D26/D4,0) | E27: =IFERROR(E26/E4,0) | F27: =IFERROR(F26/F4,0) | G27: =IFERROR(G26/G4,0) | H27: =IFERROR(H26/H4,0) | I27: =IFERROR(I26/I4,0) | ... K27: =IFERROR(K26/K4,0)
A28: FCF | B28: =B21+Assumptions!B9-Assumptions!B6 | C28: =C21+Assumptions!C9-Assumptions!C6 | D28: =D21+Assumptions!D9-Assumptions!D6 | E28: =E21+Assumptions!E9-Assumptions!E6 | F28: =F21+Assumptions!F9-Assumptions!F6 | G28: =G21+Assumptions!G9-Assumptions!G6 | H28: =H21+Assumptions!H9-Assumptions!H6 | I28: =I21+Assumptions!I9-Assumptions!I6 | ... K28: =K21+Assumptions!K9-Assumptions!K6
A29: FCF Margin % | B29: =IFERROR(B28/B4,0) | C29: =IFERROR(C28/C4,0) | D29: =IFERROR(D28/D4,0) | E29: =IFERROR(E28/E4,0) | F29: =IFERROR(F28/F4,0) | G29: =IFERROR(G28/G4,0) | H29: =IFERROR(H28/H4,0) | I29: =IFERROR(I28/I4,0) | ... K29: =IFERROR(K28/K4,0)
A32: MARGINS ANALYSIS
A33: Contribution Margin % | B33: =IFERROR((B2-B5)*100/B2,0) | C33: =IFERROR((C2-C5)*100/C2,0) | D33: =IFERROR((D2-D5)*100/D2,0) | E33: =IFERROR((E2-E5)*100/E2,0) | F33: =IFERROR((F2-F5)*100/F2,0) | G33: =IFERROR((G2-G5)*100/G2,0) | H33: =IFERROR((H2-H5)*100/H2,0) | I33: =IFERROR((I2-I5)*100/I2,0) | ... K33: =IFERROR((K2-K5)*100/K2,0)
A34: SG&A as % of Revenue | B34: =IFERROR((B9+B10+B11)/B4,0) | C34: =IFERROR((C9+C10+C11)/C4,0) | D34: =IFERROR((D9+D10+D11)/D4,0) | E34: =IFERROR((E9+E10+E11)/E4,0) | F34: =IFERROR((F9+F10+F11)/F4,0) | G34: =IFERROR((G9+G10+G11)/G4,0) | H34: =IFERROR((H9+H10+H11)/H4,0) | I34: =IFERROR((I9+I10+I11)/I4,0) | ... K34: =IFERROR((K9+K10+K11)/K4,0)
A36: CASH METRICS
A37: OCF (approx) | B37: =B21+B4-B5 | C37: =C21+C4-C5 | D37: =D21+D4-D5 | E37: =E21+E4-E5 | F37: =F21+F4-F5 | G37: =G21+G4-G5 | H37: =H21+H4-H5 | I37: =I21+I4-I5 | ... K37: =K21+K4-K5
A38: OCF Margin % | B38: =IFERROR(B33/B4,0) | C38: =IFERROR(C33/C4,0) | D38: =IFERROR(D33/D4,0) | E38: =IFERROR(E33/E4,0) | F38: =IFERROR(F33/F4,0) | G38: =IFERROR(G33/G4,0) | H38: =IFERROR(H33/H4,0) | I38: =IFERROR(I33/I4,0) | ... K38: =IFERROR(K33/K4,0)

Sheet Balance Sheet
A1: Metric | B1: 2021A | C1: 2022A | D1: 2023A | E1: 2024A | F1: 2025A | G1: 2026E | H1: 2027E | I1: 2028E | J1: 2029E | K1: 2030E
A2: ASSETS
A3: Cash & Equivalents | B3: 4000 | C3: 4000 | D3: 4000 | E3: 4000 | F3: 4000 | G3: 4000 | H3: 4000 | I3: 4000 | J3: 4000 | K3: 4000
A4: Short-term Investments | B4: 5000 | C4: 5000 | D4: 5000 | E4: 5000 | F4: 5000 | G4: 5000 | H4: 5000 | I4: 5000 | J4: 5000 | K4: 5000
A5: Content Assets (Current) | B5: 8000 | C5: 8000 | D5: 8000 | E5: 8000 | F5: 8000 | G5: 8000 | H5: 8000 | I5: 8000 | J5: 8000 | K5: 8000
A6: Other Current Assets | B6: 2000 | C6: 2000 | D6: 2000 | E6: 2000 | F6: 2000 | G6: 2000 | H6: 2000 | I6: 2000 | J6: 2000 | K6: 2000
A7: Total Current Assets | B7: =B3+B4+B5+B6 | C7: =C3+C4+C5+C6 | D7: =D3+D4+D5+D6 | E7: =E3+E4+E5+E6 | F7: =F3+F4+F5+F6 | G7: =G3+G4+G5+G6 | H7: =H3+H4+H5+H6 | I7: =I3+I4+I5+I6 | ... K7: =K3+K4+K5+K6
A8: PP&E | B8: 3500 | C8: 3500 | D8: 3500 | E8: 3500 | F8: 3500 | G8: 3500 | H8: 3500 | I8: 3500 | J8: 3500 | K8: 3500
A9: Goodwill | B9: 1200 | C9: 1200 | D9: 1200 | E9: 1200 | F9: 1200 | G9: 1200 | H9: 1200 | I9: 1200 | J9: 1200 | K9: 1200
A10: Content Assets (Non-Current) | B10: 18000 | C10: 18000 | D10: 18000 | E10: 18000 | F10: 18000 | G10: 18000 | H10: 18000 | I10: 18000 | J10: 18000 | K10: 18000
A11: Other LT Assets | B11: 1500 | C11: 1500 | D11: 1500 | E11: 1500 | F11: 1500 | G11: 1500 | H11: 1500 | I11: 1500 | J11: 1500 | K11: 1500
A12: Total Assets | B12: =B7+B8+B9+B10+B11 | C12: =C7+C8+C9+C10+C11 | D12: =D7+D8+D9+D10+D11 | E12: =E7+E8+E9+E10+E11 | F12: =F7+F8+F9+F10+F11 | G12: =G7+G8+G9+G10+G11 | H12: =H7+H8+H9+H10+H11 | I12: =I7+I8+I9+I10+I11 | ... K12: =K7+K8+K9+K10+K11
A14: LIABILITIES
A15: Current Liabilities | B15: 6500 | C15: 6500 | D15: 6500 | E15: 6500 | F15: 6500 | G15: 6500 | H15: 6500 | I15: 6500 | J15: 6500 | K15: 6500
A16: Deferred Revenue | B16: 8500 | C16: 8500 | D16: 8500 | E16: 8500 | F16: 8500 | G16: 8500 | H16: 8500 | I16: 8500 | J16: 8500 | K16: 8500
A17: Short-term Debt | B17: 2000 | C17: 2000 | D17: 2000 | E17: 2000 | F17: 2000 | G17: 2000 | H17: 2000 | I17: 2000 | J17: 2000 | K17: 2000
A18: Total Current Liabilities | B18: =B15+B16+B17 | C18: =C15+C16+C17 | D18: =D15+D16+D17 | E18: =E15+E16+E17 | F18: =F15+F16+F17 | G18: =G15+G16+G17 | H18: =H15+H16+H17 | I18: =I15+I16+I17 | ... K18: =K15+K16+K17
A19: Long-term Debt | B19: 12000 | C19: 12000 | D19: 12000 | E19: 12000 | F19: 12000 | G19: 12000 | H19: 12000 | I19: 12000 | J19: 12000 | K19: 12000
A20: Other LT Liabilities | B20: 3000 | C20: 3000 | D20: 3000 | E20: 3000 | F20: 3000 | G20: 3000 | H20: 3000 | I20: 3000 | J20: 3000 | K20: 3000
A21: Total Liabilities | B21: =B18+B19+B20 | C21: =C18+C19+C20 | D21: =D18+D19+D20 | E21: =E18+E19+E20 | F21: =F18+F19+F20 | G21: =G18+G19+G20 | H21: =H18+H19+H20 | I21: =I18+I19+I20 | ... K21: =K18+K19+K20
A23: EQUITY
A24: Common Stock | B24: 5000 | C24: 5000 | D24: 5000 | E24: 5000 | F24: 5000 | G24: 5000 | H24: 5000 | I24: 5000 | J24: 5000 | K24: 5000
A25: Retained Earnings | B25: =IFERROR(B12-B21-B24,0) | C25: =IFERROR(C12-C21-C24,0) | D25: =IFERROR(D12-D21-D24,0) | E25: =IFERROR(E12-E21-E24,0) | F25: =IFERROR(F12-F21-F24,0) | G25: =IFERROR(G12-G21-G24,0) | H25: =IFERROR(H12-H21-H24,0) | I25: =IFERROR(I12-I21-I24,0) | ... K25: =IFERROR(K12-K21-K24,0)
A26: Total Stockholders' Equity | B26: =B24+B25 | C26: =C24+C25 | D26: =D24+D25 | E26: =E24+E25 | F26: =F24+F25 | G26: =G24+G25 | H26: =H24+H25 | I26: =I24+I25 | ... K26: =K24+K25
A27: Total Liabilities & Equity | B27: =B21+B26 | C27: =C21+C26 | D27: =D21+D26 | E27: =E21+E26 | F27: =F21+F26 | G27: =G21+G26 | H27: =H21+H26 | I27: =I21+I26 | ... K27: =K21+K26
A29: BALANCE SHEET RATIOS
A30: Current Ratio | B30: =B7/B18 | C30: =C7/C18 | D30: =D7/D18 | E30: =E7/E18 | F30: =F7/F18 | G30: =G7/G18 | H30: =H7/H18 | I30: =I7/I18 | ... K30: =K7/K18
A31: Quick Ratio | B31: =IFERROR((B3+B4)/(B18),0) | C31: =IFERROR((C3+C4)/(C18),0) | D31: =IFERROR((D3+D4)/(D18),0) | E31: =IFERROR((E3+E4)/(E18),0) | F31: =IFERROR((F3+F4)/(F18),0) | G31: =IFERROR((G3+G4)/(G18),0) | H31: =IFERROR((H3+H4)/(H18),0) | I31: =IFERROR((I3+I4)/(I18),0) | ... K31: =IFERROR((K3+K4)/(K18),0)
A32: Debt-to-Equity | B32: =IFERROR(B21/B26,0) | C32: =IFERROR(C21/C26,0) | D32: =IFERROR(D21/D26,0) | E32: =IFERROR(E21/E26,0) | F32: =IFERROR(F21/F26,0) | G32: =IFERROR(G21/G26,0) | H32: =IFERROR(H21/H26,0) | I32: =IFERROR(I21/I26,0) | ... K32: =IFERROR(K21/K26,0)
A33: ROE % | B33: =IFERROR('Income Statement'!B21/B26,0) | C33: =IFERROR('Income Statement'!C21/C26,0) | D33: =IFERROR('Income Statement'!D21/D26,0) | E33: =IFERROR('Income Statement'!E21/E26,0) | F33: =IFERROR('Income Statement'!F21/F26,0) | G33: =IFERROR('Income Statement'!G21/G26,0) | H33: =IFERROR('Income Statement'!H21/H26,0) | I33: =IFERROR('Income Statement'!I21/I26,0) | ... K33: =IFERROR('Income Statement'!K21/K26,0)
A35: NOTES: Off-balance-sheet content obligations $15.3B not reflected above.

Sheet Cash Flow
A1: Metric | B1: 2021A | C1: 2022A | D1: 2023A | E1: 2024A | F1: 2025A | G1: 2026E | H1: 2027E | I1: 2028E | J1: 2029E | K1: 2030E
A2: Operating Cash Flow
A3: Net Income | B3: ='Income Statement'!B21 | C3: ='Income Statement'!C21 | D3: ='Income Statement'!D21 | E3: ='Income Statement'!E21 | F3: ='Income Statement'!F21 | G3: ='Income Statement'!G21 | H3: ='Income Statement'!H21 | I3: ='Income Statement'!I21 | ... K3: ='Income Statement'!K21
A4: D&A | B4: =Assumptions!B9 | C4: =Assumptions!C9 | D4: =Assumptions!D9 | E4: =Assumptions!E9 | F4: =Assumptions!F9 | G4: =Assumptions!G9 | H4: =Assumptions!H9 | I4: =Assumptions!I9 | ... K4: =Assumptions!K9
A5: SBC | B5: =Assumptions!B8 | C5: =Assumptions!C8 | D5: =Assumptions!D8 | E5: =Assumptions!E8 | F5: =Assumptions!F8 | G5: =Assumptions!G8 | H5: =Assumptions!H8 | I5: =Assumptions!I8 | ... K5: =Assumptions!K8
A6: Working Capital Changes | B6: =500 | C6: =500 | D6: =500 | E6: =500 | F6: =500 | G6: =500 | H6: =500 | I6: =500 | ... K6: =500
A7: Total OCF | B7: =B3+B4+B5+B6 | C7: =C3+C4+C5+C6 | D7: =D3+D4+D5+D6 | E7: =E3+E4+E5+E6 | F7: =F3+F4+F5+F6 | G7: =G3+G4+G5+G6 | H7: =H3+H4+H5+H6 | I7: =I3+I4+I5+I6 | ... K7: =K3+K4+K5+K6
A9: Investing Cash Flow
A10: CapEx | B10: =Assumptions!B6 | C10: =Assumptions!C6 | D10: =Assumptions!D6 | E10: =Assumptions!E6 | F10: =Assumptions!F6 | G10: =Assumptions!G6 | H10: =Assumptions!H6 | I10: =Assumptions!I6 | ... K10: =Assumptions!K6
A11: Content Asset Additions | B11: =1500 | C11: =1500 | D11: =1500 | E11: =1500 | F11: =1500 | G11: =1500 | H11: =1500 | I11: =1500 | ... K11: =1500
A12: Total ICF | B12: =-(B10+B11) | C12: =-(C10+C11) | D12: =-(D10+D11) | E12: =-(E10+E11) | F12: =-(F10+F11) | G12: =-(G10+G11) | H12: =-(H10+H11) | I12: =-(I10+I11) | ... K12: =-(K10+K11)
A14: Financing Cash Flow
A15: Debt Issuance | B15: =500 | C15: =500 | D15: =500 | E15: =500 | F15: =500 | G15: =500 | H15: =500 | I15: =500 | ... K15: =500
A16: Debt Repayment | B16: =-500 | C16: =-500 | D16: =-500 | E16: =-500 | F16: =-500 | G16: =-500 | H16: =-500 | I16: =-500 | ... K16: =-500
A17: Share Buybacks | B17: =-2000 | C17: =-2000 | D17: =-2000 | E17: =-2000 | F17: =-2000 | G17: =-2000 | H17: =-2000 | I17: =-2000 | ... K17: =-2000
A18: Dividends | B18: =0 | C18: =0 | D18: =0 | E18: =0 | F18: =0 | G18: =0 | H18: =0 | I18: =0 | ... K18: =0
A19: Total FCF | B19: =B15+B16+B17+B18 | C19: =C15+C16+C17+C18 | D19: =D15+D16+D17+D18 | E19: =E15+E16+E17+E18 | F19: =F15+F16+F17+F18 | G19: =G15+G16+G17+G18 | H19: =H15+H16+H17+H18 | I19: =I15+I16+I17+I18 | ... K19: =K15+K16+K17+K18
A21: Free Cash Flow | B21: =B7-B10-B11 | C21: =C7-C10-C11 | D21: =D7-D10-D11 | E21: =E7-E10-E11 | F21: =F7-F10-F11 | G21: =G7-G10-G11 | H21: =H7-H10-H11 | I21: =I7-I10-I11 | ... K21: =K7-K10-K11
A22: FCF Margin % | B22: =IFERROR(B21/'Income Statement'!B4,0) | C22: =IFERROR(C21/'Income Statement'!C4,0) | D22: =IFERROR(D21/'Income Statement'!D4,0) | E22: =IFERROR(E21/'Income Statement'!E4,0) | F22: =IFERROR(F21/'Income Statement'!F4,0) | G22: =IFERROR(G21/'Income Statement'!G4,0) | H22: =IFERROR(H21/'Income Statement'!H4,0) | I22: =IFERROR(I21/'Income Statement'!I4,0) | ... K22: =IFERROR(K21/'Income Statement'!K4,0)

Sheet Revenue Build
A1: Metric | B1: 2021A | C1: 2022A | D1: 2023A | E1: 2024A | F1: 2025A | G1: 2026E | H1: 2027E | I1: 2028E | J1: 2029E | K1: 2030E
A2: Streaming Revenue (Subs) | B2: =Assumptions!B3*Assumptions!B4*12 | C2: =Assumptions!C3*Assumptions!C4*12 | D2: =Assumptions!D3*Assumptions!D4*12 | E2: =Assumptions!E3*Assumptions!E4*12 | F2: =Assumptions!F3*Assumptions!F4*12 | G2: =Assumptions!G3*Assumptions!G4*12 | H2: =Assumptions!H3*Assumptions!H4*12 | I2: =Assumptions!I3*Assumptions!I4*12 | ... K2: =Assumptions!K3*Assumptions!K4*12
A3: Advertising Revenue | B3: =Assumptions!B10 | C3: =Assumptions!C10 | D3: =Assumptions!D10 | E3: =Assumptions!E10 | F3: =Assumptions!F10 | G3: =Assumptions!G10 | H3: =Assumptions!H10 | I3: =Assumptions!I10 | ... K3: =Assumptions!K10
A4: Total Revenue | B4: =B2+B3 | C4: =C2+C3 | D4: =D2+D3 | E4: =E2+E3 | F4: =F2+F3 | G4: =G2+G3 | H4: =H2+H3 | I4: =I2+I3 | ... K4: =K2+K3
A6: REGIONAL BREAKDOWN
A7: UCAN Subscribers (M) | B7: =Assumptions!B3*0.25 | C7: =Assumptions!C3*0.25 | D7: =Assumptions!D3*0.25 | E7: =Assumptions!E3*0.25 | F7: =Assumptions!F3*0.25 | G7: =Assumptions!G3*0.25 | H7: =Assumptions!H3*0.25 | I7: =Assumptions!I3*0.25 | ... K7: =Assumptions!K3*0.25
A8: UCAN ARPU ($) | B8: =16.50 | C8: =16.50 | D8: =16.50 | E8: =16.50 | F8: =16.50 | G8: =16.50 | H8: =16.50 | I8: =16.50 | ... K8: =16.50
A9: UCAN Revenue ($B) | B9: =B7*B8*12/1000 | C9: =C7*C8*12/1000 | D9: =D7*D8*12/1000 | E9: =E7*E8*12/1000 | F9: =F7*F8*12/1000 | G9: =G7*G8*12/1000 | H9: =H7*H8*12/1000 | I9: =I7*I8*12/1000 | ... K9: =K7*K8*12/1000
A10: EMEA Subscribers (M) | B10: =Assumptions!B3*0.30 | C10: =Assumptions!C3*0.30 | D10: =Assumptions!D3*0.30 | E10: =Assumptions!E3*0.30 | F10: =Assumptions!F3*0.30 | G10: =Assumptions!G3*0.30 | H10: =Assumptions!H3*0.30 | I10: =Assumptions!I3*0.30 | ... K10: =Assumptions!K3*0.30
A11: EMEA ARPU ($) | B11: =11.00 | C11: =11.00 | D11: =11.00 | E11: =11.00 | F11: =11.00 | G11: =11.00 | H11: =11.00 | I11: =11.00 | ... K11: =11.00
A12: EMEA Revenue ($B) | B12: =B10*B11*12/1000 | C12: =C10*C11*12/1000 | D12: =D10*D11*12/1000 | E12: =E10*E11*12/1000 | F12: =F10*F11*12/1000 | G12: =G10*G11*12/1000 | H12: =H10*H11*12/1000 | I12: =I10*I11*12/1000 | ... K12: =K10*K11*12/1000
A13: APAC Subscribers (M) | B13: =Assumptions!B3*0.30 | C13: =Assumptions!C3*0.30 | D13: =Assumptions!D3*0.30 | E13: =Assumptions!E3*0.30 | F13: =Assumptions!F3*0.30 | G13: =Assumptions!G3*0.30 | H13: =Assumptions!H3*0.30 | I13: =Assumptions!I3*0.30 | ... K13: =Assumptions!K3*0.30
A14: APAC ARPU ($) | B14: =8.50 | C14: =8.50 | D14: =8.50 | E14: =8.50 | F14: =8.50 | G14: =8.50 | H14: =8.50 | I14: =8.50 | ... K14: =8.50
A15: APAC Revenue ($B) | B15: =B13*B14*12/1000 | C15: =C13*C14*12/1000 | D15: =D13*D14*12/1000 | E15: =E13*E14*12/1000 | F15: =F13*F14*12/1000 | G15: =G13*G14*12/1000 | H15: =H13*H14*12/1000 | I15: =I13*I14*12/1000 | ... K15: =K13*K14*12/1000
A16: LATAM Subscribers (M) | B16: =Assumptions!B3*0.15 | C16: =Assumptions!C3*0.15 | D16: =Assumptions!D3*0.15 | E16: =Assumptions!E3*0.15 | F16: =Assumptions!F3*0.15 | G16: =Assumptions!G3*0.15 | H16: =Assumptions!H3*0.15 | I16: =Assumptions!I3*0.15 | ... K16: =Assumptions!K3*0.15
A17: LATAM ARPU ($) | B17: =7.00 | C17: =7.00 | D17: =7.00 | E17: =7.00 | F17: =7.00 | G17: =7.00 | H17: =7.00 | I17: =7.00 | ... K17: =7.00
A18: LATAM Revenue ($B) | B18: =B16*B17*12/1000 | C18: =C16*C17*12/1000 | D18: =D16*D17*12/1000 | E18: =E16*E17*12/1000 | F18: =F16*F17*12/1000 | G18: =G16*G17*12/1000 | H18: =H16*H17*12/1000 | I18: =I16*I17*12/1000 | ... K18: =K16*K17*12/1000

Sheet DCF Valuation
A1: WACC CALCULATION | G1: Notes
A2: Risk-Free Rate (%) | B2: =Assumptions!B13*100 | G2: DCF Calculation
A3: Equity Risk Premium (%) | B3: =Assumptions!B14*100 | G3: Risk-free rate
A4: Beta | B4: =Assumptions!B15 | G4: ERP added
A5: Cost of Equity (%) | B5: =Assumptions!B16*100 | G5: Beta multiplier
A6: Cost of Debt (%) | B6: =Assumptions!B17*100 | G6: Equity cost
A7: Tax Shield (%) | B7: =Assumptions!B18/100 | G7: Debt cost
A8: WACC (%) | B8: =Assumptions!B19*100 | G8: Tax benefit
G9: WACC
A10: DCF VALUATION (2026E-2030E)
A11: Year | B11: 2026E | C11: 2027E | D11: 2028E | E11: 2029E | F11: 2030E
A12: Free Cash Flow ($B) | B12: ='Cash Flow'!G21 | C12: ='Cash Flow'!H21 | D12: ='Cash Flow'!I21 | E12: ='Cash Flow'!J21 | F12: ='Cash Flow'!K21
A13: Discount Factor | B13: =1/(1+Assumptions!B19)^1 | C13: =1/(1+Assumptions!B19)^2 | D13: =1/(1+Assumptions!B19)^3 | E13: =1/(1+Assumptions!B19)^4 | F13: =1/(1+Assumptions!B19)^5
A14: PV of FCF ($B) | B14: =B12*B13 | C14: =C12*C13 | D14: =D12*D13 | E14: =E12*E13 | F14: =F12*F13
A16: Sum of PV FCFs | B16: =SUM(B14:F14)
A18: Terminal Value Calc
A19: 2030E FCF ($B) | B19: =B12
A20: Terminal Growth Rate | B20: =Assumptions!B20
A21: WACC | B21: =Assumptions!B19
A22: Terminal Value | B22: =B17*(1+B18)/(B19-B18)
A23: PV of Terminal Value | B23: =B20*1/(1+Assumptions!B19)^5
A25: EQUITY VALUATION
A26: PV of FCF (2026-2030) | B26: =B16
A27: PV of Terminal Value | B27: =B22
A28: Enterprise Value | B28: =B27+B28
A29: Less: Net Debt | B29: =12000
A30: Equity Value ($B) | B30: =B29-B30
A31: Shares Outstanding (M) | B31: =425.5
A32: Value Per Share | B32: =B31/B32*1000
A34: SENSITIVITY ANALYSIS
A35: WACC vs Terminal Growth
B36: WACC (rows) / Terminal Growth (cols)
B37: 2.0% | C37: 2.5% | D37: 3.0% | E37: 3.5% | F37: 4.0%
A38: 8.0% | B38: =B24/(0.08-0.02) | C38: =B24/(0.08-0.025) | D38: =B24/(0.08-0.03) | E38: =B24/(0.08-0.035) | F38: =B24/(0.08-0.04)
A39: 8.5% | B39: =B24/(0.085-0.02) | C39: =B24/(0.085-0.025) | D39: =B24/(0.085-0.03) | E39: =B24/(0.085-0.035) | F39: =B24/(0.085-0.04)
A40: 9.2% | B40: =B24/(0.092-0.02) | C40: =B24/(0.092-0.025) | D40: =B24/(0.092-0.03) | E40: =B24/(0.092-0.035) | F40: =B24/(0.092-0.04)
A41: 9.5% | B41: =B24/(0.095-0.02) | C41: =B24/(0.095-0.025) | D41: =B24/(0.095-0.03) | E41: =B24/(0.095-0.035) | F41: =B24/(0.095-0.04)
A42: 10.0% | B42: =B24/(0.10-0.02) | C42: =B24/(0.10-0.025) | D42: =B24/(0.10-0.03) | E42: =B24/(0.10-0.035) | F42: =B24/(0.10-0.04)
A43: 10.5% | B43: =B24/(0.105-0.02) | C43: =B24/(0.105-0.025) | D43: =B24/(0.105-0.03) | E43: =B24/(0.105-0.035) | F43: =B24/(0.105-0.04)
A44: 11.0% | B44: =B24/(0.11-0.02) | C44: =B24/(0.11-0.025) | D44: =B24/(0.11-0.03) | E44: =B24/(0.11-0.035) | F44: =B24/(0.11-0.04)

Sheet SOTP Valuation
A1: SUM-OF-THE-PARTS VALUATION
A3: Segment | B3: Value ($B) | C3: Probability | D3: Risk-Adj Value ($B) | E3: % of Total
A4: Core Streaming | B4: 300 | C4: 0.95 | D4: =B4*C4 | E4: =D4/IFERROR(SUM(D$4:D$8),1)
A5: Advertising Business | B5: 40.5 | C5: 0.7 | D5: =B5*C5 | E5: =D5/IFERROR(SUM(D$4:D$8),1)
A6: Live Sports (Future) | B6: 20 | C6: 0.4 | D6: =B6*C6 | E6: =D6/IFERROR(SUM(D$4:D$8),1)
A7: Gaming & Interactivity | B7: 15 | C7: 0.25 | D7: =B7*C7 | E7: =D7/IFERROR(SUM(D$4:D$8),1)
A8: ARPU Expansion Upside | B8: 15 | C8: 0.6 | D8: =B8*C8 | E8: =D8/IFERROR(SUM(D$4:D$8),1)
A10: Total SOTP Value ($B) | B10: =SUM(D4:D8)
A11: Less: Net Debt ($B) | B11: 12
A12: Equity Value ($B) | B12: =B12-B13
A13: Shares Outstanding (M) | B13: 425.5
A14: Value Per Share | B14: =B14/B15*1000
A16: SENSITIVITY: Probability Adjustments
A17: Conservative (Lower Probs) | B17: =B4*0.75 | C17: =B5*0.60 | D17: =B6*0.30 | E17: =B7*0.15 | F17: =B8*0.40 | G17: =SUM(D2:D7)
A18: Bull Case (Higher Probs) | B18: =B4*0.98 | C18: =B5*0.85 | D18: =B6*0.55 | E18: =B7*0.40 | F18: =B8*0.75 | G18: =SUM(D3:D8)

Sheet Scenario Analysis
A1: SCENARIO ANALYSIS
A3: Scenario | B3: Price Target ($) | C3: Probability % | D3: Risk-Adjusted Value ($) | E3: vs Current ($94.96) | F3: Upside/(Downside) %
A4: Tail Bull | B4: 160 | C4: 8 | D4: =B5*C5 | E4: =D5-$D$5 | F4: =E5/$D$5
A5: Bull | B5: 138 | C5: 30 | D5: =B6*C6 | E5: =D6-$D$5 | F5: =E6/$D$6
A6: Base Case | B6: 109 | C6: 35 | D6: =B7*C7 | E6: =D7-$D$5 | F6: =E7/$D$7
A7: Bear | B7: 68 | C7: 22 | D7: =B8*C8 | E7: =D8-$D$5 | F7: =E8/$D$8
A8: Tail Bear | B8: 45 | C8: 5 | D8: =B9*C9 | E8: =D9-$D$5 | F8: =E9/$D$9
A10: Blended Fair Value | B10: =SUM(D5:D9)
A11: Current Price | B11: 94.96
A12: Implied Upside | B12: =B11-B12
A13: Implied Upside % | B13: =B13/B12

Sheet Comps
A1: Company | B1: EV/Revenue | C1: EV/EBITDA | D1: P/E | E1: Rev Growth % | F1: EBITDA Margin % | G1: FCF Yield % | H1: Beta | I1: Price Target
A2: Netflix | B2: ='Income Statement'!B4/'DCF Valuation'!B2 | C2: 3.5 | D2: 32.5 | E2: 14.5 | F2: 25 | G2: 18.5 | H2: 1.15 | I2: 109
A3: Disney | B3: 2.1 | C3: 4.2 | D3: 28 | E3: 8.5 | F3: 22 | G3: 12.5 | H3: 1.05 | I3: 95.5
A4: Warner Bros Discovery | B4: 1.8 | C4: 3.8 | D4: 15.5 | E4: 6 | F4: 18.5 | G4: 8 | H4: 1.2 | I4: 58
A5: Paramount Global | B5: 1.5 | C5: 4 | D5: 12 | E5: 5 | F5: 15 | G5: 5.5 | H5: 1.18 | I5: 52
A6: Amazon (Media) | B6: 0.6 | C6: 12.5 | D6: 45 | E6: 12 | F6: 8 | G6: 6.5 | H6: 1.25 | I6: 210
A7: Spotify | B7: 1.8 | C7: 8.5 | D7: 85 | E7: 16 | F7: 10 | G7: 4.5 | H7: 1.35 | I7: 185
A8: Alphabet (YouTube) | B8: 5.5 | C8: 22 | D8: 28.5 | E8: 13 | F8: 35 | G8: 15.5 | H8: 1.1 | I8: 185
A9: Apple (TV+) | B9: 28 | C9: 35 | D9: 32 | E9: 7 | F9: 32 | G9: 22 | H9: 1.15 | I9: 245
A11: NFLX Median | B11: =MEDIAN(B2:B8) | C11: =MEDIAN(C2:C8) | D11: =MEDIAN(D2:D8) | E11: =MEDIAN(E2:E8) | F11: =MEDIAN(F2:F8) | G11: =MEDIAN(G2:G8) | H11: =MEDIAN(H2:H8)
A13: MULTIPLE HISTORY & TRENDS
A14: NFLX 1Y Avg EV/Revenue | B14: 3.2 | C14: 3.1 | D14: 3 | E14: 3.1 | F14: =AVERAGE(B18:E18)
A15: NFLX 1Y Avg P/E | B15: 35 | C15: 34.5 | D15: 33 | E15: 32.5 | F15: =AVERAGE(B19:E19)
A16: Peer Avg EV/Revenue | B16: =AVERAGE(C2:C8) | C16: =AVERAGE(C2:C8) | D16: =AVERAGE(C2:C8) | E16: =AVERAGE(C2:C8)
A17: Premium/Discount % | B17: =IFERROR((B18/B20-1),0) | C17: =IFERROR((C18/C20-1),0) | D17: =IFERROR((D18/D20-1),0) | E17: =IFERROR((E18/E20-1),0)

Sheet Agent Scores
A1: Agent # | B1: Score (0-10) | C1: Confidence | D1: Assessment | E1: Signal
A2: 1 | B2: 7.5 | C2: 0.85 | D2: Financial Health | E2: BULLISH
A3: 2 | B3: 6.8 | C3: 0.8 | D3: Content Moat | E3: BULLISH
A4: 3 | B4: 7.2 | C4: 0.88 | D4: Ad Tier Growth | E4: BULLISH
A5: 4 | B5: 6.5 | C5: 0.75 | D5: Subscriber Momentum | E5: NEUTRAL
A6: 5 | B6: 7.1 | C6: 0.82 | D6: Pricing Power | E6: BULLISH
A7: 6 | B7: 6.3 | C7: 0.7 | D7: Churn Risk | E7: NEUTRAL
A8: 7 | B8: 7.6 | C8: 0.9 | D8: Balance Sheet | E8: BULLISH
A9: 8 | B9: 6.9 | C9: 0.78 | D9: Management | E9: NEUTRAL
A10: 9 | B10: 5.8 | C10: 0.65 | D10: Content Spending | E10: BEARISH
A11: 10 | B11: 6.4 | C11: 0.72 | D11: Macro Sensitivity | E11: NEUTRAL
A12: 11 | B12: 7 | C12: 0.8 | D12: Competitive Pos | E12: BULLISH
A13: 12 | B13: 6.7 | C13: 0.75 | D13: FCF Generation | E13: BULLISH
... A20: 19 | B20: 6.2 | C20: 0.72 | D20: Optionality | E20: NEUTRAL
A22: AGGREGATE METRICS
A23: Average Score | B23: =AVERAGE(B2:B19)
A24: Average Confidence | B24: =AVERAGE(C2:C19)
A25: Bull Signal Count | B25: =COUNTIF(E2:E19,"BULLISH")
A26: Neutral Signal Count | B26: =COUNTIF(E2:E19,"NEUTRAL")
A27: Bear Signal Count | B27: =COUNTIF(E2:E19,"BEARISH")

Sheet Catalyst Calendar
A1: Date (Est.) | B1: Catalyst | C1: Type | D1: Probability % | E1: Price Impact %
A2: Q2 2026 | B2: Ad tier $3B run rate | C2: REVENUE | D2: 0.65 | E2: 7.5
A3: Q3 2026 | B3: NFL rights expansion | C3: STRATEGIC | D3: 0.45 | E3: 11.5
A4: Q3 2026 | B4: France tax investigation | C4: RISK | D4: 0.5 | E4: -5.5
A5: Q4 2026 | B5: Squid Game S3 launch | C5: CONTENT | D5: 0.75 | E5: 4
A6: Q4 2026 | B6: Gaming monetization plan | C6: PRODUCT | D6: 0.4 | E6: 6
A7: Q1 2027 | B7: Price increase rollout | C7: PRICING | D7: 0.7 | E7: 3
A8: Q1 2027 | B8: Ad platform self-serve | C8: PRODUCT | D8: 0.55 | E8: 4.5
A9: H1 2027 | B9: India 50M subs | C9: EXPANSION | D9: 0.45 | E9: 3
A10: H2 2027 | B10: CDN-as-a-service pilot | C10: STRATEGIC | D10: 0.2 | E10: 5.5
A11: RISK | B11: Content miss/slate fail | C11: RISK | D11: 0.2 | E11: -8.5
A12: RISK | B12: Ad CPM collapse | C12: RISK | D12: 0.25 | E12: -11.5
A13: RISK | B13: Tariff escalation | C13: MACRO | D13: 0.3 | E13: -7.5

Sheet Position Sizing
A1: POSITION SIZING FRAMEWORK
A3: Fair Value (DCF) | B3: =DCF Valuation!B32
A4: Current Price | B4: 94.96
A5: Margin of Safety | B5: =B3/B4-1
A7: KELLY CRITERION | B7: Optimal Position % | C7: Conservative %
A8: Edge per trade | B8: 0.15
A9: Win Probability | B9: 0.65
A10: Risk/Reward Ratio | B10: 1.5
A11: Kelly % = (Prob*RR - (1-Prob))/RR | B11: =IFERROR((B9*B11-(1-B9))/B11,0)
A12: Recommended Position Size | B12: =B12*0.25 | C12: =B12*0.10
A14: INVESTOR PROFILES
A15: Profile | B15: Entry Level | C15: Exit Level (Bull) | D15: Exit Level (Bear)
A16: Aggressive | B16: 94.96 | C16: 138 | D16: 68
A17: Moderate | B17: 94.96 | C17: 120 | D17: 75
A18: Conservative | B18: 94.96 | C18: 110 | D18: 80
A19: Very Conservative | B19: 94.96 | C19: 100 | D19: 85
A21: Position Risk/Reward
A22: Avg Entry | B22: =AVERAGE(B16:B19)
A23: Avg Bull Target | B23: =AVERAGE(C16:C19)
A24: Avg Bear Target | B24: =AVERAGE(D16:D19)
A25: Avg R/R Ratio | B25: =IFERROR((B23-B22)/(B22-B24),0)

Sheet Delta Intelligence
A1: Signal Category | B1: Metric | C1: Current Value | D1: YoY Change | E1: Direction | F1: Confidence | G1: Bloomberg Has? | H1: Edge vs Street | I1: Source
A2: App Analytics | B2: Netflix App DAU (M) | C2: 8.5 | D2: +12% | E2: BULLISH | F2: HIGH | G2: NO | H2: YES | I2: SensorTower
A3: App Analytics | B3: Ad-tier opt-in % | C3: 42% | D3: +18pp | E3: BULLISH | F3: MEDIUM | G3: NO | H3: YES | I3: Internal
A4: App Analytics | B4: Games DAU (M) | C4: 1.2 | D4: +35% | E4: NEUTRAL | F4: LOW | G4: NO | H4: YES | I4: Internal
A5: Content Performance | B5: Squid Game S2 views (28d) | C5: 126.2M | D5: +45% | E5: BULLISH | F5: HIGH | G5: NO | H5: YES | I5: Netflix
A6: Content Performance | B6: Hit rate (>50M views) | C6: 8/20 | D6: -2 YoY | E6: BEARISH | F6: MEDIUM | G6: NO | H6: YES | I6: Internal
A7: Content Performance | B7: Original vs Licensed % | C7: 65/35 | D7: +5pp orig | E7: BULLISH | F7: MEDIUM | G7: NO | H7: YES | I7: Internal
A8: Web Traffic | B8: Netflix.com visitors (M/mo) | C8: 450 | D8: +5% | E8: NEUTRAL | F8: MEDIUM | G8: NO | H8: YES | I8: SimilarWeb
A9: Web Traffic | B9: Cancel page traffic (M/mo) | C9: 12 | D9: +18% | E9: BEARISH | F9: MEDIUM | G9: NO | H9: YES | I9: SimilarWeb
A10: Web Traffic | B10: Upgrade queries (M/mo) | C10: 3.2 | D10: +25% | E10: BULLISH | F10: LOW | G10: NO | H10: YES | I10: Internal
A11: Talent Flow | B11: Eng job postings | C11: 847 | D11: +22% | E11: BULLISH | F11: HIGH | G11: NO | H11: YES | I11: LinkedIn
A12: Talent Flow | B12: Ad tech postings | C12: 234 | D12: +68% | E12: BULLISH | F12: HIGH | G12: NO | H12: YES | I12: LinkedIn
A13: Talent Flow | B13: CEO approval % | C13: 78% | D13: -3pp | E13: NEUTRAL | F13: MEDIUM | G13: PARTIAL | H13: YES | I13: Glassdoor
A14: Talent Flow | B14: Avg tenure (yrs) | C14: 3.4 | D14: -0.2 | E14: BEARISH | F14: LOW | G14: NO | H14: NO | I14: Glassdoor
A15: Advertiser Intel | B15: Ad CPM ($) | C15: 31.5 | D15: +15% | E15: BULLISH | F15: MEDIUM | G15: NO | H15: YES | I15: Agency talks
A16: Advertiser Intel | B16: Retention rate % | C16: 72% | D16: NEW | E16: NEUTRAL | F16: LOW | G16: NO | H16: YES | I16: Internal
A17: Advertiser Intel | B17: Programmatic fill % | C17: 85% | D17: +20pp | E17: BULLISH | F17: MEDIUM | G17: NO | H17: YES | I17: Internal
A18: Social Intelligence | B18: Reddit sentiment | C18: 0.58 | D18: -0.05 | E18: NEUTRAL | F18: LOW | G18: NO | H18: NO | I18: Reddit
A19: Social Intelligence | B19: Twitter mentions/day (K) | C19: 12 | D19: +8% | E19: NEUTRAL | F19: LOW | G19: NO | H19: NO | I19: Twitter
A20: Social Intelligence | B20: TikTok Netflix views (B) | C20: 2.1 | D20: +45% | E20: BULLISH | F20: MEDIUM | G20: NO | H20: YES | I20: TikTok
A21: Subscriber Intel | B21: Pwd-share conversion (M) | C21: 30 | D21: EXCEEDED | E21: BULLISH | F21: HIGH | G21: NO | H21: YES | I21: Netflix
A22: Subscriber Intel | B22: Churn rate % | C22: 2.0% | D22: -0.3pp | E22: BULLISH | F22: HIGH | G22: NO | H22: YES | I22: Netflix
A23: Subscriber Intel | B23: APAC adds (M/Q) | C23: 4.2 | D23: +25% | E23: BULLISH | F23: MEDIUM | G23: NO | H23: YES | I23: Netflix
A24: Supply Chain | B24: Content spend/title ($M) | C24: 8.5 | D24: +12% | E24: NEUTRAL | F24: MEDIUM | G24: NO | H24: NO | I24: Variety
A25: Supply Chain | B25: Post-prod AI adoption % | C25: 45% | D25: +25pp | E25: BULLISH | F25: MEDIUM | G25: NO | H25: YES | I25: Industry
A26: IP Activity | B26: Patent filings (TTM) | C26: 187 | D26: +15% | E26: BULLISH | F26: LOW | G26: PARTIAL | H26: YES | I26: USPTO
A27: IP Activity | B27: Gaming patents | C27: 23 | D27: +8 | E27: BULLISH | F27: LOW | G27: NO | H27: YES | I27: USPTO
A28: Device Partners | B28: Smart TV agreements | C28: 7000 | D28: +500 | E28: BULLISH | F28: HIGH | G28: NO | H28: YES | I28: Industry
A29: Competitive Intel | B29: Disney+ losses to Netflix (M) | C29: 2.1 | D29: NEW | E29: BULLISH | F29: MEDIUM | G29: NO | H29: YES | I29: Reports
A30: Insider Activity | B30: Net insider sales ($M) | C30: -287 | D30: -$287M | E30: BEARISH | F30: HIGH | G30: PARTIAL | H30: YES | I30: SEC
A31: Insider Activity | B31: Insider buy trans (90d) | C31: 0 | D31: 0 | E31: BEARISH | F31: HIGH | G31: NO | H31: NO | I31: SEC
A32: Regulatory | B32: France tax investigation | C32: Active | D32: Ongoing | E32: BEARISH | F32: MEDIUM | G32: NO | H32: YES | I32: News
A33: Regulatory | B33: EU DSA compliance ($M) | C33: 180 | D33: +80 | E33: BEARISH | F33: LOW | G33: NO | H33: YES | I33: Est.
A35: Mobile Usage | B35: iOS Daily Sessions (M) | C35: 12.5 | D35: +8% | E35: NEUTRAL | F35: MEDIUM | G35: NO | H35: YES | I35: App Annie
A36: Mobile Usage | B36: Android Daily Sessions (M) | C36: 9.2 | D36: +14% | E36: BULLISH | F36: MEDIUM | G36: NO | H36: YES | I36: App Annie
A37: Mobile Usage | B37: Session Length (min) | C37: 67.5 | D37: -2.1% | E37: BEARISH | F37: MEDIUM | G37: NO | H37: NO | I37: App Annie
A38: CDN Performance | B38: Open Connect % traffic | C38: 89 | D38: +3pp | E38: NEUTRAL | F38: HIGH | G38: NO | H38: YES | I38: Internal
A39: CDN Performance | B39: CDN cost per GB (est) | C39: 0.002 | D39: -5% | E39: BULLISH | F39: MEDIUM | G39: NO | H39: YES | I39: Industry
A40: Streaming Quality | B40: % streams 4K | C40: 28 | D40: +4pp | E40: BULLISH | F40: MEDIUM | G40: NO | H40: YES | I40: Internal
A41: Streaming Quality | B41: Rebuffer rate % | C41: 0.8 | D41: -0.1pp | E41: BULLISH | F41: MEDIUM | G41: NO | H41: YES | I41: Internal
...

Sheet Content Analysis
A1: Genre | B1: # Titles (2025) | C1: Avg Cost ($M) | D1: Avg Views (M) | E1: ROI % | F1: Hit Rate % | G1: Trend | H1: 2026E Budget | I1: Strategic Value
A2: Drama | B2: 12 | C2: 45 | D2: 180.5 | E2: 4.01 | F2: 83.3 | G2: BULLISH | H2: 15 | I2: High
A3: Comedy | B3: 8 | C3: 25 | D3: 95.3 | E3: 3.81 | F3: 75 | G3: NEUTRAL | H3: 12 | I3: Moderate
A4: Action/Adventure | B4: 6 | C4: 55 | D4: 210.5 | E4: 3.83 | F4: 66.7 | G4: NEUTRAL | H4: 14 | I4: High
A5: Documentary | B5: 15 | C5: 8.5 | D5: 35.2 | E5: 4.14 | F5: 86.7 | G5: BULLISH | H5: 8.5 | I5: Moderate
A6: Kids/Family | B6: 10 | C6: 20 | D6: 80.5 | E6: 4.03 | F6: 80 | G6: BULLISH | H6: 11 | I6: High
A7: International | B7: 25 | C7: 12 | D7: 55.8 | E7: 4.65 | F7: 92 | G7: BULLISH | H7: 18 | I7: Very High
A8: Limited Series | B8: 18 | C8: 35 | D8: 125.3 | E8: 3.58 | F8: 61.1 | G8: NEUTRAL | H8: 16 | I8: High
A9: Unscripted/Reality | B9: 20 | C9: 5 | D9: 45.2 | E9: 9.04 | F9: 95 | G9: BULLISH | H9: 12 | I9: High
A10: Anime | B10: 14 | C10: 3.5 | D10: 75.5 | E10: 21.57 | F10: 100 | G10: BULLISH | H10: 6.5 | I10: Moderate
A11: Licensing/Classics | B11: 30 | C11: 0.5 | D11: 25 | E11: 50 | F11: 100 | G11: NEUTRAL | H11: 3 | I11: Moderate
A13: PORTFOLIO STATS
A14: Total Titles | B14: =SUM(B2:B11) | C14: AVG | D14: =AVERAGE(D2:D11) | E14: =AVERAGE(E2:E11) | F14: =AVERAGE(F2:F11) | H14: =SUM(H2:H11)
A15: Original Content | B15: 65% | C15: Est. | D15: =SUM(D2:D11)*0.65 | E15: =AVERAGE(E2:E11) | F15: 85% | G15: BULLISH | H15: =SUM(H2:H11)*0.75 | I15: Core
A16: Licensed Content | B16: 35% | C16: Est. | D16: =SUM(D2:D11)*0.35 | E16: =AVERAGE(E2:E11) | F16: 90% | G16: NEUTRAL | H16: =SUM(H2:H11)*0.25 | I16: Support

Sheet Subscriber Cohorts
A1: Cohort | B1: Subscribers (M) | C1: ARPU ($) | D1: Monthly Churn % | E1: LTV ($) | F1: CAC ($) | G1: LTV/CAC
A2: Early Adopters (2010-2015) | B2: 45 | C2: 15.5 | D2: 1.5 | E2: 620 | F2: 35 | G2: =E2/F2
A3: Growth Period (2015-2018) | B3: 95 | C3: 13.25 | D3: 2 | E3: 530 | F3: 32 | G3: =E3/F3
A4: Mature US (2018-2020) | B4: 65 | C4: 14.95 | D4: 2.3 | E4: 598 | F4: 38 | G4: =E4/F4
A5: Ad-Tier Converts (2022-2023) | B5: 70 | C5: 10.5 | D5: 3.5 | E5: 420 | F5: 28 | G5: =E5/F5
A6: Post-Crackdown (2023-2025) | B6: 30 | C6: 12 | D6: 2.8 | E6: 480 | F6: 25 | G6: =E6/F6
A7: New International (2024-2025) | B7: 50 | C7: 8.5 | D7: 3.2 | E7: 340 | F7: 22 | G7: =E7/F7
A8: Password Share (2025) | B8: 20 | C8: 12.5 | D8: 4 | E8: 500 | F8: 30 | G8: =E8/F8
A9: Games Adopters | B9: 15 | C9: 13.75 | D9: 2.2 | E9: 550 | F9: 32 | G9: =E9/F9
A11: PORTFOLIO | B11: =SUM(B2:B8) | C11: =AVERAGE(C2:C8) | D11: =AVERAGE(D2:D8) | E11: =AVERAGE(E2:E8) | F11: =AVERAGE(F2:F8) | G11: =AVERAGE(G2:G8)
A12: Premium Tier | B12: =SUM(B2:B4) | C12: =AVERAGE(C2:C4) | D12: =AVERAGE(D2:D4) | E12: =AVERAGE(E2:E4) | F12: =AVERAGE(F2:F4) | G12: =AVERAGE(G2:G4)
A13: Standard Tier | B13: =SUM(B5:B6) | C13: =AVERAGE(C5:C6) | D13: =AVERAGE(D5:D6) | E13: =AVERAGE(E5:E6) | F13: =AVERAGE(F5:F6) | G13: =AVERAGE(G5:G6)
A14: Ad-Supported Tier | B14: =SUM(B7:B8) | C14: =AVERAGE(C7:C8) | D14: =AVERAGE(D7:D8) | E14: =AVERAGE(E7:E8) | F14: =AVERAGE(F7:F8) | G14: =AVERAGE(G7:G8)

Sheet Risk Matrix
A1: Risk Category | B1: Risk Item | C1: Probability % | D1: Impact ($M) | E1: Risk Score | F1: Mitigation
A2: BUSINESS RISK | B2: Content miss/slate failure | C2: 0.2 | D2: 800 | E2: =C3*D3 | F2: Diversify slate, greenlight process
A3: BUSINESS RISK | B3: Password sharing collapse | C3: 0.15 | D3: 500 | E3: =C4*D4 | F3: Graduated price increases
A4: BUSINESS RISK | B4: Ad CPM compression | C4: 0.25 | D4: 1200 | E4: =C5*D5 | F4: Premium ad products, higher margins
A5: BUSINESS RISK | B5: Churn acceleration | C5: 0.22 | D5: 1500 | E5: =C6*D6 | F5: Content quality, new products
A6: COMPETITIVE RISK | B6: Disney+ aggressive pricing | C6: 0.3 | D6: 600 | E6: =C7*D7 | F6: Content moat, bundling options
A7: COMPETITIVE RISK | B7: YouTube/TikTok cannibalization | C7: 0.35 | D7: 400 | E7: =C8*D8 | F7: Short-form content strategy
A8: COMPETITIVE RISK | B8: Amazon/Apple expansion | C8: 0.25 | D8: 500 | E8: =C9*D9 | F8: Exclusive content, bundling
A9: MACRO RISK | B9: Recession impact on spending | C9: 0.18 | D9: 1000 | E9: =C10*D10 | F9: Ad tier, price flexibility
A10: MACRO RISK | B10: Tariff escalation (content) | C10: 0.3 | D10: 300 | E10: =C11*D11 | F10: Diversify production locations
A11: MACRO RISK | B11: FX headwinds | C11: 0.4 | D11: 400 | E11: =C12*D12 | F11: Natural hedges, pricing discipline
A12: REGULATORY RISK | B12: France tax investigation | C12: 0.5 | D12: 500 | E12: =C13*D13 | F12: Compliance, settlement reserve
A13: REGULATORY RISK | B13: EU DSA compliance | C13: 0.65 | D13: 200 | E13: =C14*D14 | F13: Build AI moderation systems
... A19: PEOPLE RISK | B19: Labor relations issues | C19: 0.15 | D19: 100 | E19: =C20*D20 | F19: Fair labor practices
